Workbook

Sheet FRONT PAGE
A1: PIMSAT COLLEGES, INC. McArthur Highway, Bolosan District, Dagupan City COLLEGE OF MARITIME EDUCATION Bachelor of Science in Marine Transportation
A9: A.Y. 2025-2026 2ND SEMESTER
A10: NAVIGATION 7 - VOYAGE PLANNING
A14: PASSAGE PLAN
F20: NAME OF VESSEL
H22: VOYAGE NO:
C24: PORT OF DEPARTURE: | J24: PORT OF ARRIVAL:
A28: YEAR & SECTION: | F28: MEMBERS:
A29: GROUP NO:
B33: PREPARED BY: | G33: VALIDATED BY: | L33: APPROVED BY:
B34: 2/M CHRISTIAN PAUL R. FERNANDEZ | G34: CAPT. CHARLIE V. ZAPANTA | L34: DEAN VALENTINO H. FERRE
B35: Instructor | G35: Assessor | L35: Dean, College of Maritime Education

Sheet GENERAL INFORMATION
A1: PIMSAT COLLEGES, INC. McArthur Highway, Bolosan District, Dagupan City COLLEGE OF MARITIME EDUCATION Bachelor of Science in Marine Transportation
A3: NAVIGATION 7 - VOYAGE PLANNING
A4: GENERAL INFORMATION
A6: YEAR & SECTION: | C6: ='FRONT PAGE'!C28 -> 0 | E6: MEMBERS: | G6: 1 | H6: ='FRONT PAGE'!H28 -> 0 | L6: 3 | M6: ='FRONT PAGE'!M28 -> 0
A7: GROUP NO: | C7: ='FRONT PAGE'!C29 -> 0 | G7: 2 | H7: ='FRONT PAGE'!H29 -> 0 | L7: 4 | M7: ='FRONT PAGE'!M29 -> 0
A9: NAME OF VESSEL: | C9: ='FRONT PAGE'!F21 -> 0 | G9: DEPARTURE PORT INFORMATION | L9: ARRIVAL PORT INFORMATION
A10: VOYAGE NO: | C10: ='FRONT PAGE'!H23 -> 0 | G10: NAME OF PORT: | I10: ='FRONT PAGE'!C25 -> 0 | L10: NAME OF PORT: | N10: ='FRONT PAGE'!J25 -> 0
A11: VESSEL'S CONDITION: | G11: ETD: | L11: ETA:
A12: TARGET SPEED: | G12: TIME ZONE: | L12: TIME ZONE:
A13: TOTAL STEAMING TIME:
A14: TOTAL DISTANCE: | G14: MINIMUM UNDER KEEL CLEARANCE (UKC) | M14: SQUAT
A15: MAX. HEIGHT ABOVE KEEL: | G15: A) In Deep Coastal waters / Ocean Passages: | L15: METERS | M15: OPEN WATERS | P15: METERS
A16: MAX. SUMMER DRAFT: | G16: B) In Shallow Coastal / Port waters: | L16: METERS | M16: CONFINED WATERS | P16: METERS
A17: MAX. BEAM OF VESSEL | G17: A) In Deep Coastal waters / Ocean Passages: A minimum under keel clearance of twice the maximum summer draft of the vessel shall be maintained at all times during the voyage. B) In Shallow Coastal / Port waters: A minimum under-keel clearance amounting to 10 per cent of ship's deepest draft or one meter, whichever is greater, shall be maintained at all times. | M17: The vessel can determine the squat by using the formula S= cb x v2/100 for Open Waters and S = 2 x cb x v2/100 for Confined Waters where Cb is the block coefficient of the vessel and v2 is the square of the speed the vessel.
A18: BLOCK COEFFICIENT:
A19: FWA:
A20: DEPARTURE DRAFT | C20: FWD:
C21: MID: | G21: DEPTH PARAMETERS
C22: AFT: | G22: SHALLOW CONTOUR | K22: M | L22: = Max. Dynamic Draft in dock water - Height of Tide
A23: ARRIVAL DRAFT | C23: FWD: | G23: SAFETY CONTOUR | K23: M | L23: Safety Depth = Safety Depth
C24: MID: | G24: SAFETY DEPTH | K24: M | L24: = Max. Dynamic Draft + reqd UKC in Shallow water +CATZOC Accuracy - Height of Tide
C25: AFT: | G25: DEEP CONTOUR | K25: M | L25: = Max. Dynamic Draft + Max. Static Draft

Sheet CHARTS & PUBLICATIONS
A1: PIMSAT COLLEGES, INC. McArthur Highway, Bolosan District, Dagupan City COLLEGE OF MARITIME EDUCATION Bachelor of Science in Marine Transportation
A3: NAVIGATION 7 - VOYAGE PLANNING
A4: CHARTS & PUBLICATIONS
A6: YEAR & SECTION: | C6: ='FRONT PAGE'!C28 -> 0 | E6: MEMBERS: | H6: 1 | I6: ='FRONT PAGE'!H28 -> 0 | N6: 3 | O6: ='FRONT PAGE'!M28 -> 0
A7: GROUP NO: | C7: ='FRONT PAGE'!C29 -> 0 | H7: 2 | I7: ='FRONT PAGE'!H29 -> 0 | N7: 4 | O7: ='FRONT PAGE'!M29 -> 0
A9: LIST OF NAUTICAL CHARTS USE IN VOYAGE
A10: NO. | B10: CHART NO. | C10: TITLE | G10: SCALE | K10: NO. | L10: CHART NO. | M10: TITLE | Q10: SCALE
A11: 1 | K11: 36
A12: 2 | K12: 37
A13: 3 | K13: 38
A14: 4 | K14: 39
A15: 5 | K15: 40
A16: 6 | K16: 41
A17: 7 | K17: 42
A18: 8 | K18: 43
A19: 9 | K19: 44
A20: 10 | K20: 45
A21: 11 | K21: 46
A22: 12 | K22: 47
... A45: 35 | K45: 70
A49: LIST OF NAUTICAL PUBLICATIONS USE IN VOYAGE
A51: ADMIRALTY LIST OF RADIO SIGNALS | K51: ADMIRALTY SAILING DIRECTION
A52: NP NO. | C52: VOLUME | D52: TITLE | K52: NP NO. | M52: VOLUME | N52: TITLE
A65: ADMIRALTY LIST OF LIGHTS AND FOG SIGNALS | K65: ADMIRALTY TIDE TABLES / TOTAL TIDE / TIDAL STREAM ATLAS
A66: NP NO. | C66: VOLUME | D66: TITLE | K66: NP NO. | M66: VOLUME | N66: TITLE

Sheet DEPARTURE - Berth to Pilot
A1: PIMSAT COLLEGES, INC. McArthur Highway, Bolosan District, Dagupan City COLLEGE OF MARITIME EDUCATION Bachelor of Science in Marine Transportation
A2: NAV 7 - VOYAGE PLANNING
A4: YEAR & SECTION: | C4: ='FRONT PAGE'!C28 -> 0 | Q4: MEMBERS: | U4: 1 | W4: ='FRONT PAGE'!H28 -> 0 | AA4: 3 | AB4: ='FRONT PAGE'!M28 -> 0
A5: GROUP NO: | C5: ='FRONT PAGE'!C29 -> 0 | U5: 2 | W5: ='FRONT PAGE'!H29 -> 0 | AA5: 4 | AB5: ='FRONT PAGE'!M29 -> 0
A6: DEPARTURE PORT: Passage from Berth to Pilot Station
A7: NAME OF VESSEL: | C7: ='FRONT PAGE'!F21 -> 0 | P7: DEPARTURE: | R7: ='FRONT PAGE'!C25 -> 0 | U7: ARRIVAL: | X7: ='FRONT PAGE'!J25 -> 0 | Z7: VOYAGE NO: | AB7: ='FRONT PAGE'!H23 -> 0
A8: NO. | B8: NAME/ REFERENCE | C8: POSITION | N8: T/CO | O8: DIST | P8: SP'D | Q8: F'M | R8: TO | S8: ESTIMATED MINIMUM UKC / E (ENOUGH) | T8: POSITION | U8: TIME CORR. (min.) | W8: ETA/ETP (L.T.) DD/MM/YY | X8: METHODS OF OBTAINING POSITION | Y8: POSITION FIXING INTERVAL | Z8: CALL MASTER | AA8: WATCH LEVEL | AB8: CHART NO. | AC8: GARBAGE/SEWAGE DISPOSAL | AD8: REMARKS:
T9: FIX SYSTEM
D10: Lat | E10: Long | F10: 漸長緯度 | G10: 緯差 | H10: Long (360) | I10: 経差 | J10: 漸長緯度差 | L10: 針路 | M10: 距離 | T10: PRIMARY
T11: SECONDARY
A12: 0 | D12: =TRUNC(C12)+((C12-TRUNC(C12))/0.6) -> 0 | E12: =TRUNC(C13)+((C13-TRUNC(C13))/0.6) -> 0 | F12: =ROUND(((LOG10(TAN(PI()/4+(D12/2*PI()/180)))*7915.7046)-(3437.7468*((0.0816968^2*SIN(D12*PI()/180))+(0.0816968^4/3*((SIN(D12*PI()/180))^3))+(0.0816968^6/5*((SIN(D12*PI()/180))^5))))),2) -> 0 | H12: =IF(E12<0,E12+360,E12) -> 0 | Q12: 0 | R12: ='GENERAL INFORMATION'!C14 -> 0 | T12: RADAR | W12: 45982.208
G13: =ABS(D12-D14)*60 -> 0 | I13: =ABS(H12-H14)*60 -> 0 | J13: =ABS(F12-F14) -> 0 | K13: =IF(AND(D12<D14,H12=H14),0,IF(AND(D12>D14,H12=H14),180,IF(AND(D12=D14,H12<H14),90,IF(AND(D12=D14,H12>H14),270,(ATAN(I13/J13)*180/PI()))))) -> #DIV/0! | L13: =IF(OR(K13=0,K13=90,K13=180,K13=270),K13,IF(AND(D12<D14,H12<H14),K13,IF(AND(D12<D14,H12>H14),360-K13,IF(AND(D12>D14,H12<H14),180-K13,IF(AND(D12>D14,H12>H14),180+K13))))) -> #DIV/0! | M13: =(IF(I13=0,G13,IF(G13=0,COS(D14*PI()/180)*I13,G13/COS(K13*PI()/180)))) -> 0 | N13: =IF(C15="","",ROUND(L13,1)) | O13: =IF(C15="","",ROUND(M13,1)) | T13: EVERY 5 MIN | V13: =(O13/P13+U13/60)/24 -> #VALUE!
A14: 1 | D14: =TRUNC(C14)+((C14-TRUNC(C14))/0.6) -> 0 | E14: =TRUNC(C15)+((C15-TRUNC(C15))/0.6) -> 0 | F14: =ROUND(((LOG10(TAN(PI()/4+(D14/2*PI()/180)))*7915.7046)-(3437.7468*((0.0816968^2*SIN(D14*PI()/180))+(0.0816968^4/3*((SIN(D14*PI()/180))^3))+(0.0816968^6/5*((SIN(D14*PI()/180))^5))))),2) -> 0 | H14: =IF(E14<0,E14+360,E14) -> 0 | Q14: =IF(O13="","",Q12+O13) | R14: =IF(O13="","",R12-O13) | T14: RADAR | W14: =IF(P13="","",W12+V13)
G15: =ABS(D14-D16)*60 -> 0 | I15: =ABS(H14-H16)*60 -> 0 | J15: =ABS(F14-F16) -> 0 | K15: =IF(AND(D14<D16,H14=H16),0,IF(AND(D14>D16,H14=H16),180,IF(AND(D14=D16,H14<H16),90,IF(AND(D14=D16,H14>H16),270,(ATAN(I15/J15)*180/PI()))))) -> #DIV/0! | L15: =IF(OR(K15=0,K15=90,K15=180,K15=270),K15,IF(AND(D14<D16,H14<H16),K15,IF(AND(D14<D16,H14>H16),360-K15,IF(AND(D14>D16,H14<H16),180-K15,IF(AND(D14>D16,H14>H16),180+K15))))) -> #DIV/0! | M15: =(IF(I15=0,G15,IF(G15=0,COS(D16*PI()/180)*I15,G15/COS(K15*PI()/180)))) -> 0 | N15: =IF(C17="","",ROUND(L15,1)) | O15: =IF(C17="","",ROUND(M15,1)) | T15: EVERY 5 MIN | V15: =(O15/P15+U15/60)/24 -> #VALUE!
A16: 2 | D16: =TRUNC(C16)+((C16-TRUNC(C16))/0.6) -> 0 | E16: =TRUNC(C17)+((C17-TRUNC(C17))/0.6) -> 0 | F16: =ROUND(((LOG10(TAN(PI()/4+(D16/2*PI()/180)))*7915.7046)-(3437.7468*((0.0816968^2*SIN(D16*PI()/180))+(0.0816968^4/3*((SIN(D16*PI()/180))^3))+(0.0816968^6/5*((SIN(D16*PI()/180))^5))))),2) -> 0 | H16: =IF(E16<0,E16+360,E16) -> 0 | Q16: =IF(O15="","",Q14+O15) | R16: =IF(O15="","",R14-O15) | T16: RADAR | W16: =IF(P15="","",W14+V15)
G17: =ABS(D16-D18)*60 -> 0 | I17: =ABS(H16-H18)*60 -> 0 | J17: =ABS(F16-F18) -> 0 | K17: =IF(AND(D16<D18,H16=H18),0,IF(AND(D16>D18,H16=H18),180,IF(AND(D16=D18,H16<H18),90,IF(AND(D16=D18,H16>H18),270,(ATAN(I17/J17)*180/PI()))))) -> #DIV/0! | L17: =IF(OR(K17=0,K17=90,K17=180,K17=270),K17,IF(AND(D16<D18,H16<H18),K17,IF(AND(D16<D18,H16>H18),360-K17,IF(AND(D16>D18,H16<H18),180-K17,IF(AND(D16>D18,H16>H18),180+K17))))) -> #DIV/0! | M17: =(IF(I17=0,G17,IF(G17=0,COS(D18*PI()/180)*I17,G17/COS(K17*PI()/180)))) -> 0 | N17: =IF(C19="","",ROUND(L17,1)) | O17: =IF(C19="","",ROUND(M17,1)) | T17: EVERY 5 MIN | V17: =(O17/P17+U17/60)/24 -> #VALUE!
A18: 3 | D18: =TRUNC(C18)+((C18-TRUNC(C18))/0.6) -> 0 | E18: =TRUNC(C19)+((C19-TRUNC(C19))/0.6) -> 0 | F18: =ROUND(((LOG10(TAN(PI()/4+(D18/2*PI()/180)))*7915.7046)-(3437.7468*((0.0816968^2*SIN(D18*PI()/180))+(0.0816968^4/3*((SIN(D18*PI()/180))^3))+(0.0816968^6/5*((SIN(D18*PI()/180))^5))))),2) -> 0 | H18: =IF(E18<0,E18+360,E18) -> 0 | Q18: =IF(O17="","",Q16+O17) | R18: =IF(O17="","",R16-O17) | T18: RADAR | W18: =IF(P17="","",W16+V17)
G19: =ABS(D18-D20)*60 -> 0 | I19: =ABS(H18-H20)*60 -> 0 | J19: =ABS(F18-F20) -> 0 | K19: =IF(AND(D18<D20,H18=H20),0,IF(AND(D18>D20,H18=H20),180,IF(AND(D18=D20,H18<H20),90,IF(AND(D18=D20,H18>H20),270,(ATAN(I19/J19)*180/PI()))))) -> #DIV/0! | L19: =IF(OR(K19=0,K19=90,K19=180,K19=270),K19,IF(AND(D18<D20,H18<H20),K19,IF(AND(D18<D20,H18>H20),360-K19,IF(AND(D18>D20,H18<H20),180-K19,IF(AND(D18>D20,H18>H20),180+K19))))) -> #DIV/0! | M19: =(IF(I19=0,G19,IF(G19=0,COS(D20*PI()/180)*I19,G19/COS(K19*PI()/180)))) -> 0 | N19: =IF(C21="","",ROUND(L19,1)) | O19: =IF(C21="","",ROUND(M19,1)) | T19: EVERY 5 MIN | V19: =(O19/P19+U19/60)/24 -> #VALUE!
A20: 4 | D20: =TRUNC(C20)+((C20-TRUNC(C20))/0.6) -> 0 | E20: =TRUNC(C21)+((C21-TRUNC(C21))/0.6) -> 0 | F20: =ROUND(((LOG10(TAN(PI()/4+(D20/2*PI()/180)))*7915.7046)-(3437.7468*((0.0816968^2*SIN(D20*PI()/180))+(0.0816968^4/3*((SIN(D20*PI()/180))^3))+(0.0816968^6/5*((SIN(D20*PI()/180))^5))))),2) -> 0 | H20: =IF(E20<0,E20+360,E20) -> 0 | Q20: =IF(O19="","",Q18+O19) | R20: =IF(O19="","",R18-O19) | T20: RADAR | W20: =IF(P19="","",W18+V19)
G21: =ABS(D20-D22)*60 -> 0 | I21: =ABS(H20-H22)*60 -> 0 | J21: =ABS(F20-F22) -> 0 | K21: =IF(AND(D20<D22,H20=H22),0,IF(AND(D20>D22,H20=H22),180,IF(AND(D20=D22,H20<H22),90,IF(AND(D20=D22,H20>H22),270,(ATAN(I21/J21)*180/PI()))))) -> #DIV/0! | L21: =IF(OR(K21=0,K21=90,K21=180,K21=270),K21,IF(AND(D20<D22,H20<H22),K21,IF(AND(D20<D22,H20>H22),360-K21,IF(AND(D20>D22,H20<H22),180-K21,IF(AND(D20>D22,H20>H22),180+K21))))) -> #DIV/0! | M21: =(IF(I21=0,G21,IF(G21=0,COS(D22*PI()/180)*I21,G21/COS(K21*PI()/180)))) -> 0 | N21: =IF(C23="","",ROUND(L21,1)) | O21: =IF(C23="","",ROUND(M21,1)) | T21: EVERY 5MIN. | V21: =(O21/P21+U21/60)/24 -> #VALUE!
A22: 5 | D22: =TRUNC(C22)+((C22-TRUNC(C22))/0.6) -> 0 | E22: =TRUNC(C23)+((C23-TRUNC(C23))/0.6) -> 0 | F22: =ROUND(((LOG10(TAN(PI()/4+(D22/2*PI()/180)))*7915.7046)-(3437.7468*((0.0816968^2*SIN(D22*PI()/180))+(0.0816968^4/3*((SIN(D22*PI()/180))^3))+(0.0816968^6/5*((SIN(D22*PI()/180))^5))))),2) -> 0 | H22: =IF(E22<0,E22+360,E22) -> 0 | Q22: =IF(O21="","",Q20+O21) | R22: =IF(O21="","",R20-O21) | T22: RADAR | W22: =IF(P21="","",W20+V21)
G23: =ABS(D22-D24)*60 -> 0 | I23: =ABS(H22-H24)*60 -> 0 | J23: =ABS(F22-F24) -> 0 | K23: =IF(AND(D22<D24,H22=H24),0,IF(AND(D22>D24,H22=H24),180,IF(AND(D22=D24,H22<H24),90,IF(AND(D22=D24,H22>H24),270,(ATAN(I23/J23)*180/PI()))))) -> #DIV/0! | L23: =IF(OR(K23=0,K23=90,K23=180,K23=270),K23,IF(AND(D22<D24,H22<H24),K23,IF(AND(D22<D24,H22>H24),360-K23,IF(AND(D22>D24,H22<H24),180-K23,IF(AND(D22>D24,H22>H24),180+K23))))) -> #DIV/0! | M23: =(IF(I23=0,G23,IF(G23=0,COS(D24*PI()/180)*I23,G23/COS(K23*PI()/180)))) -> 0 | N23: =IF(C25="","",ROUND(L23,1)) | O23: =IF(C25="","",ROUND(M23,1)) | T23: EVERY 5 MIN | V23: =(O23/P23+U23/60)/24 -> #VALUE!
A24: 6 | D24: =TRUNC(C24)+((C24-TRUNC(C24))/0.6) -> 0 | E24: =TRUNC(C25)+((C25-TRUNC(C25))/0.6) -> 0 | F24: =ROUND(((LOG10(TAN(PI()/4+(D24/2*PI()/180)))*7915.7046)-(3437.7468*((0.0816968^2*SIN(D24*PI()/180))+(0.0816968^4/3*((SIN(D24*PI()/180))^3))+(0.0816968^6/5*((SIN(D24*PI()/180))^5))))),2) -> 0 | H24: =IF(E24<0,E24+360,E24) -> 0 | Q24: =IF(O23="","",Q22+O23) | R24: =IF(O23="","",R22-O23) | T24: RADAR/GPS | W24: =IF(P23="","",W22+V23)
G25: =ABS(D24-D26)*60 -> 0 | I25: =ABS(H24-H26)*60 -> 0 | J25: =ABS(F24-F26) -> 0 | K25: =IF(AND(D24<D26,H24=H26),0,IF(AND(D24>D26,H24=H26),180,IF(AND(D24=D26,H24<H26),90,IF(AND(D24=D26,H24>H26),270,(ATAN(I25/J25)*180/PI()))))) -> #DIV/0! | L25: =IF(OR(K25=0,K25=90,K25=180,K25=270),K25,IF(AND(D24<D26,H24<H26),K25,IF(AND(D24<D26,H24>H26),360-K25,IF(AND(D24>D26,H24<H26),180-K25,IF(AND(D24>D26,H24>H26),180+K25))))) -> #DIV/0! | M25: =(IF(I25=0,G25,IF(G25=0,COS(D26*PI()/180)*I25,G25/COS(K25*PI()/180)))) -> 0 | N25: =IF(C27="","",ROUND(L25,1)) | O25: =IF(C27="","",ROUND(M25,1)) | T25: EVERY 5MIN. | V25: =(O25/P25+U25/60)/24 -> #VALUE!
A26: 7 | D26: =TRUNC(C26)+((C26-TRUNC(C26))/0.6) -> 0 | E26: =TRUNC(C27)+((C27-TRUNC(C27))/0.6) -> 0 | F26: =ROUND(((LOG10(TAN(PI()/4+(D26/2*PI()/180)))*7915.7046)-(3437.7468*((0.0816968^2*SIN(D26*PI()/180))+(0.0816968^4/3*((SIN(D26*PI()/180))^3))+(0.0816968^6/5*((SIN(D26*PI()/180))^5))))),2) -> 0 | H26: =IF(E26<0,E26+360,E26) -> 0 | Q26: =IF(O25="","",Q24+O25) | R26: =IF(O25="","",R24-O25) | T26: RADAR/GPS | W26: =IF(P25="","",W24+V25)
G27: =ABS(D26-D28)*60 -> 0 | I27: =ABS(H26-H28)*60 -> 0 | J27: =ABS(F26-F28) -> 0 | K27: =IF(AND(D26<D28,H26=H28),0,IF(AND(D26>D28,H26=H28),180,IF(AND(D26=D28,H26<H28),90,IF(AND(D26=D28,H26>H28),270,(ATAN(I27/J27)*180/PI()))))) -> #DIV/0! | L27: =IF(OR(K27=0,K27=90,K27=180,K27=270),K27,IF(AND(D26<D28,H26<H28),K27,IF(AND(D26<D28,H26>H28),360-K27,IF(AND(D26>D28,H26<H28),180-K27,IF(AND(D26>D28,H26>H28),180+K27))))) -> #DIV/0! | M27: =(IF(I27=0,G27,IF(G27=0,COS(D28*PI()/180)*I27,G27/COS(K27*PI()/180)))) -> 0 | N27: =IF(C29="","",ROUND(L27,1)) | O27: =IF(C29="","",ROUND(M27,1)) | T27: EVERY 5MIN. | V27: =(O27/P27+U27/60)/24 -> #VALUE!
A28: 8 | D28: =TRUNC(C28)+((C28-TRUNC(C28))/0.6) -> 0 | E28: =TRUNC(C29)+((C29-TRUNC(C29))/0.6) -> 0 | F28: =ROUND(((LOG10(TAN(PI()/4+(D28/2*PI()/180)))*7915.7046)-(3437.7468*((0.0816968^2*SIN(D28*PI()/180))+(0.0816968^4/3*((SIN(D28*PI()/180))^3))+(0.0816968^6/5*((SIN(D28*PI()/180))^5))))),2) -> 0 | H28: =IF(E28<0,E28+360,E28) -> 0 | Q28: =IF(O27="","",Q26+O27) | R28: =IF(O27="","",R26-O27) | T28: RADR/GPS | W28: =IF(P27="","",W26+V27)
G29: =ABS(D28-D30)*60 -> 0 | I29: =ABS(H28-H30)*60 -> 0 | J29: =ABS(F28-F30) -> 0 | K29: =IF(AND(D28<D30,H28=H30),0,IF(AND(D28>D30,H28=H30),180,IF(AND(D28=D30,H28<H30),90,IF(AND(D28=D30,H28>H30),270,(ATAN(I29/J29)*180/PI()))))) -> #DIV/0! | L29: =IF(OR(K29=0,K29=90,K29=180,K29=270),K29,IF(AND(D28<D30,H28<H30),K29,IF(AND(D28<D30,H28>H30),360-K29,IF(AND(D28>D30,H28<H30),180-K29,IF(AND(D28>D30,H28>H30),180+K29))))) -> #DIV/0! | M29: =(IF(I29=0,G29,IF(G29=0,COS(D30*PI()/180)*I29,G29/COS(K29*PI()/180)))) -> 0 | N29: =IF(C31="","",ROUND(L29,1)) | O29: =IF(C31="","",ROUND(M29,1)) | T29: EVERY 5MIN. | V29: =(O29/P29+U29/60)/24 -> #VALUE!
A30: 9 | D30: =TRUNC(C30)+((C30-TRUNC(C30))/0.6) -> 0 | E30: =TRUNC(C31)+((C31-TRUNC(C31))/0.6) -> 0 | F30: =ROUND(((LOG10(TAN(PI()/4+(D30/2*PI()/180)))*7915.7046)-(3437.7468*((0.0816968^2*SIN(D30*PI()/180))+(0.0816968^4/3*((SIN(D30*PI()/180))^3))+(0.0816968^6/5*((SIN(D30*PI()/180))^5))))),2) -> 0 | H30: =IF(E30<0,E30+360,E30) -> 0 | Q30: =IF(O29="","",Q28+O29) | R30: =IF(O29="","",R28-O29) | T30: RADAR/GPS | W30: =IF(P29="","",W28+V29)
G31: =ABS(D30-D32)*60 -> 0 | I31: =ABS(H30-H32)*60 -> 0 | J31: =ABS(F30-F32) -> 0 | K31: =IF(AND(D30<D32,H30=H32),0,IF(AND(D30>D32,H30=H32),180,IF(AND(D30=D32,H30<H32),90,IF(AND(D30=D32,H30>H32),270,(ATAN(I31/J31)*180/PI()))))) -> #DIV/0! | L31: =IF(OR(K31=0,K31=90,K31=180,K31=270),K31,IF(AND(D30<D32,H30<H32),K31,IF(AND(D30<D32,H30>H32),360-K31,IF(AND(D30>D32,H30<H32),180-K31,IF(AND(D30>D32,H30>H32),180+K31))))) -> #DIV/0! | M31: =(IF(I31=0,G31,IF(G31=0,COS(D32*PI()/180)*I31,G31/COS(K31*PI()/180)))) -> 0 | N31: =IF(C33="","",ROUND(L31,1)) | O31: =IF(C33="","",ROUND(M31,1)) | T31: EVERY 5 MIN | V31: =(O31/P31+U31/60)/24 -> #VALUE!
A32: 10 | D32: =TRUNC(C32)+((C32-TRUNC(C32))/0.6) -> 0 | E32: =TRUNC(C33)+((C33-TRUNC(C33))/0.6) -> 0 | F32: =ROUND(((LOG10(TAN(PI()/4+(D32/2*PI()/180)))*7915.7046)-(3437.7468*((0.0816968^2*SIN(D32*PI()/180))+(0.0816968^4/3*((SIN(D32*PI()/180))^3))+(0.0816968^6/5*((SIN(D32*PI()/180))^5))))),2) -> 0 | H32: =IF(E32<0,E32+360,E32) -> 0 | Q32: =IF(O31="","",Q30+O31) | R32: =IF(O31="","",R30-O31) | T32: RADAR/GPS | W32: =IF(P31="","",W30+V31)
G33: =ABS(D32-D34)*60 -> 0 | I33: =ABS(H32-H34)*60 -> 0 | J33: =ABS(F32-F34) -> 0 | K33: =IF(AND(D32<D34,H32=H34),0,IF(AND(D32>D34,H32=H34),180,IF(AND(D32=D34,H32<H34),90,IF(AND(D32=D34,H32>H34),270,(ATAN(I33/J33)*180/PI()))))) -> #DIV/0! | L33: =IF(OR(K33=0,K33=90,K33=180,K33=270),K33,IF(AND(D32<D34,H32<H34),K33,IF(AND(D32<D34,H32>H34),360-K33,IF(AND(D32>D34,H32<H34),180-K33,IF(AND(D32>D34,H32>H34),180+K33))))) -> #DIV/0! | M33: =(IF(I33=0,G33,IF(G33=0,COS(D34*PI()/180)*I33,G33/COS(K33*PI()/180)))) -> 0 | N33: =IF(C35="","",ROUND(L33,1)) | O33: =IF(C35="","",ROUND(M33,1)) | T33: EVERY 15 MIN | V33: =(O33/P33+U33/60)/24 -> #VALUE!
A34: 11 | D34: =TRUNC(C34)+((C34-TRUNC(C34))/0.6) -> 0 | E34: =TRUNC(C35)+((C35-TRUNC(C35))/0.6) -> 0 | F34: =ROUND(((LOG10(TAN(PI()/4+(D34/2*PI()/180)))*7915.7046)-(3437.7468*((0.0816968^2*SIN(D34*PI()/180))+(0.0816968^4/3*((SIN(D34*PI()/180))^3))+(0.0816968^6/5*((SIN(D34*PI()/180))^5))))),2) -> 0 | H34: =IF(E34<0,E34+360,E34) -> 0 | Q34: =IF(O33="","",Q32+O33) | R34: =IF(O33="","",R32-O33) | T34: RADAR/GPS | W34: =IF(P33="","",W32+V33)
G35: =ABS(D34-D36)*60 -> 0 | I35: =ABS(H34-H36)*60 -> 0 | J35: =ABS(F34-F36) -> 0 | K35: =IF(AND(D34<D36,H34=H36),0,IF(AND(D34>D36,H34=H36),180,IF(AND(D34=D36,H34<H36),90,IF(AND(D34=D36,H34>H36),270,(ATAN(I35/J35)*180/PI()))))) -> #DIV/0! | L35: =IF(OR(K35=0,K35=90,K35=180,K35=270),K35,IF(AND(D34<D36,H34<H36),K35,IF(AND(D34<D36,H34>H36),360-K35,IF(AND(D34>D36,H34<H36),180-K35,IF(AND(D34>D36,H34>H36),180+K35))))) -> #DIV/0! | M35: =(IF(I35=0,G35,IF(G35=0,COS(D36*PI()/180)*I35,G35/COS(K35*PI()/180)))) -> 0 | N35: =IF(C37="","",ROUND(L35,1)) | O35: =IF(C37="","",ROUND(M35,1)) | T35: EVERY 15 MIN | V35: =(O35/P35+U35/60)/24 -> #VALUE!
A36: 12 | D36: =TRUNC(C36)+((C36-TRUNC(C36))/0.6) -> 0 | E36: =TRUNC(C37)+((C37-TRUNC(C37))/0.6) -> 0 | F36: =ROUND(((LOG10(TAN(PI()/4+(D36/2*PI()/180)))*7915.7046)-(3437.7468*((0.0816968^2*SIN(D36*PI()/180))+(0.0816968^4/3*((SIN(D36*PI()/180))^3))+(0.0816968^6/5*((SIN(D36*PI()/180))^5))))),2) -> 0 | H36: =IF(E36<0,E36+360,E36) -> 0 | Q36: =IF(O35="","",Q34+O35) | R36: =IF(O35="","",R34-O35) | T36: RADAR/GPS | W36: =IF(P35="","",W34+V35)
G37: =ABS(D36-D38)*60 -> 0 | I37: =ABS(H36-H38)*60 -> 0 | J37: =ABS(F36-F38) -> 0 | K37: =IF(AND(D36<D38,H36=H38),0,IF(AND(D36>D38,H36=H38),180,IF(AND(D36=D38,H36<H38),90,IF(AND(D36=D38,H36>H38),270,(ATAN(I37/J37)*180/PI()))))) -> #DIV/0! | L37: =IF(OR(K37=0,K37=90,K37=180,K37=270),K37,IF(AND(D36<D38,H36<H38),K37,IF(AND(D36<D38,H36>H38),360-K37,IF(AND(D36>D38,H36<H38),180-K37,IF(AND(D36>D38,H36>H38),180+K37))))) -> #DIV/0! | M37: =(IF(I37=0,G37,IF(G37=0,COS(D38*PI()/180)*I37,G37/COS(K37*PI()/180)))) -> 0 | N37: =IF(C39="","",ROUND(L37,1)) | O37: =IF(C39="","",ROUND(M37,1)) | T37: EVERY 30 MIN | V37: =(O37/P37+U37/60)/24 -> #VALUE!
A38: 13 | D38: =TRUNC(C38)+((C38-TRUNC(C38))/0.6) -> 0 | E38: =TRUNC(C39)+((C39-TRUNC(C39))/0.6) -> 0 | F38: =ROUND(((LOG10(TAN(PI()/4+(D38/2*PI()/180)))*7915.7046)-(3437.7468*((0.0816968^2*SIN(D38*PI()/180))+(0.0816968^4/3*((SIN(D38*PI()/180))^3))+(0.0816968^6/5*((SIN(D38*PI()/180))^5))))),2) -> 0 | H38: =IF(E38<0,E38+360,E38) -> 0 | Q38: =IF(O37="","",Q36+O37) | R38: =IF(O37="","",R36-O37) | T38: RADAR/GPS | W38: =IF(P37="","",W36+V37)
G39: =ABS(D38-D40)*60 -> 0 | I39: =ABS(H38-H40)*60 -> 0 | J39: =ABS(F38-F40) -> 0 | K39: =IF(AND(D38<D40,H38=H40),0,IF(AND(D38>D40,H38=H40),180,IF(AND(D38=D40,H38<H40),90,IF(AND(D38=D40,H38>H40),270,(ATAN(I39/J39)*180/PI()))))) -> #DIV/0! | L39: =IF(OR(K39=0,K39=90,K39=180,K39=270),K39,IF(AND(D38<D40,H38<H40),K39,IF(AND(D38<D40,H38>H40),360-K39,IF(AND(D38>D40,H38<H40),180-K39,IF(AND(D38>D40,H38>H40),180+K39))))) -> #DIV/0! | M39: =(IF(I39=0,G39,IF(G39=0,COS(D40*PI()/180)*I39,G39/COS(K39*PI()/180)))) -> 0 | N39: =IF(C41="","",ROUND(L39,1)) | O39: =IF(C41="","",ROUND(M39,1)) | T39: EVERY 30 MIN | V39: =(O39/P39+U39/60)/24 -> #VALUE!
A40: 14 | D40: =TRUNC(C40)+((C40-TRUNC(C40))/0.6) -> 0 | E40: =TRUNC(C41)+((C41-TRUNC(C41))/0.6) -> 0 | F40: =ROUND(((LOG10(TAN(PI()/4+(D40/2*PI()/180)))*7915.7046)-(3437.7468*((0.0816968^2*SIN(D40*PI()/180))+(0.0816968^4/3*((SIN(D40*PI()/180))^3))+(0.0816968^6/5*((SIN(D40*PI()/180))^5))))),2) -> 0 | H40: =IF(E40<0,E40+360,E40) -> 0 | Q40: =IF(O39="","",Q38+O39) | R40: =IF(O39="","",R38-O39) | T40: GPS | W40: =IF(P39="","",W38+V39)
G41: =ABS(D40-D42)*60 -> 0 | I41: =ABS(H40-H42)*60 -> 0 | J41: =ABS(F40-F42) -> 0 | K41: =IF(AND(D40<D42,H40=H42),0,IF(AND(D40>D42,H40=H42),180,IF(AND(D40=D42,H40<H42),90,IF(AND(D40=D42,H40>H42),270,(ATAN(I41/J41)*180/PI()))))) -> #DIV/0! | L41: =IF(OR(K41=0,K41=90,K41=180,K41=270),K41,IF(AND(D40<D42,H40<H42),K41,IF(AND(D40<D42,H40>H42),360-K41,IF(AND(D40>D42,H40<H42),180-K41,IF(AND(D40>D42,H40>H42),180+K41))))) -> #DIV/0! | M41: =(IF(I41=0,G41,IF(G41=0,COS(D42*PI()/180)*I41,G41/COS(K41*PI()/180)))) -> 0 | N41: =IF(C43="","",ROUND(L41,1)) | O41: =IF(C43="","",ROUND(M41,1)) | T41: EVERY 1 HR. | V41: =(O41/P41+U41/60)/24 -> #VALUE!
...

Sheet SEA PASSAGE - Pilot to Pilot 
A1: PIMSAT COLLEGES, INC. McArthur Highway, Bolosan District, Dagupan City COLLEGE OF MARITIME EDUCATION Bachelor of Science in Marine Transportation
A2: NAV 7 - VOYAGE PLANNING
A4: YEAR & SECTION: | C4: ='FRONT PAGE'!C28 -> 0 | Q4: MEMBERS: | U4: 1 | W4: ='FRONT PAGE'!H28 -> 0 | AA4: 3 | AB4: ='FRONT PAGE'!M28 -> 0
A5: GROUP NO: | C5: ='FRONT PAGE'!C29 -> 0 | U5: 2 | W5: ='FRONT PAGE'!H29 -> 0 | AA5: 4 | AB5: ='FRONT PAGE'!M29 -> 0
A6: Sea Passage from Pilot to Pilot
A7: NAME OF VESSEL: | C7: ='FRONT PAGE'!F21 -> 0 | P7: DEPARTURE: | R7: ='FRONT PAGE'!C25 -> 0 | U7: ARRIVAL: | X7: ='FRONT PAGE'!J25 -> 0 | Z7: VOYAGE NO: | AB7: ='FRONT PAGE'!H23 -> 0
A8: NO. | B8: NAME/ REFERENCE | C8: POSITION | N8: T/CO | O8: DIST | P8: SP'D | Q8: F'M | R8: TO | S8: ESTIMATED MINIMUM UKC / E (ENOUGH) | T8: POSITION | U8: TIME CORR. (min.) | W8: ETA/ETP (L.T.) DD/MM/YY | X8: METHODS OF OBTAINING POSITION | Y8: POSITION FIXING INTERVAL | Z8: CALL MASTER | AA8: WATCH LEVEL | AB8: CHART NO. | AC8: GARBAGE/SEWAGE DISPOSAL | AD8: REMARKS:
T9: FIX SYSTEM
D10: Lat | E10: Long | F10: 漸長緯度 | G10: 緯差 | H10: Long (360) | I10: 経差 | J10: 漸長緯度差 | L10: 針路 | M10: 距離 | T10: PRIMARY
T11: SECONDARY
A12: 0 | D12: =TRUNC(C12)+((C12-TRUNC(C12))/0.6) -> 0 | E12: =TRUNC(C13)+((C13-TRUNC(C13))/0.6) -> 0 | F12: =ROUND(((LOG10(TAN(PI()/4+(D12/2*PI()/180)))*7915.7046)-(3437.7468*((0.0816968^2*SIN(D12*PI()/180))+(0.0816968^4/3*((SIN(D12*PI()/180))^3))+(0.0816968^6/5*((SIN(D12*PI()/180))^5))))),2) -> 0 | H12: =IF(E12<0,E12+360,E12) -> 0 | Q12: 0 | T12: RADAR | W12: 45987.675
G13: =ABS(D12-D14)*60 -> 0 | I13: =ABS(H12-H14)*60 -> 0 | J13: =ABS(F12-F14) -> 0 | K13: =IF(AND(D12<D14,H12=H14),0,IF(AND(D12>D14,H12=H14),180,IF(AND(D12=D14,H12<H14),90,IF(AND(D12=D14,H12>H14),270,(ATAN(I13/J13)*180/PI()))))) -> #DIV/0! | L13: =IF(OR(K13=0,K13=90,K13=180,K13=270),K13,IF(AND(D12<D14,H12<H14),K13,IF(AND(D12<D14,H12>H14),360-K13,IF(AND(D12>D14,H12<H14),180-K13,IF(AND(D12>D14,H12>H14),180+K13))))) -> #DIV/0! | M13: =(IF(I13=0,G13,IF(G13=0,COS(D14*PI()/180)*I13,G13/COS(K13*PI()/180)))) -> 0 | N13: =IF(C15="","",ROUND(L13,1)) | O13: =IF(C15="","",ROUND(M13,1)) | T13: EVERY 5 MIN | V13: =(O13/P13+U13/60)/24 -> #VALUE!
A14: 1 | D14: =TRUNC(C14)+((C14-TRUNC(C14))/0.6) -> 0 | E14: =TRUNC(C15)+((C15-TRUNC(C15))/0.6) -> 0 | F14: =ROUND(((LOG10(TAN(PI()/4+(D14/2*PI()/180)))*7915.7046)-(3437.7468*((0.0816968^2*SIN(D14*PI()/180))+(0.0816968^4/3*((SIN(D14*PI()/180))^3))+(0.0816968^6/5*((SIN(D14*PI()/180))^5))))),2) -> 0 | H14: =IF(E14<0,E14+360,E14) -> 0 | Q14: =IF(O13="","",Q12+O13) | R14: =IF(O13="","",R12-O13) | T14: RADAR | W14: =IF(P13="","",W12+V13)
G15: =ABS(D14-D16)*60 -> 0 | I15: =ABS(H14-H16)*60 -> 0 | J15: =ABS(F14-F16) -> 0 | K15: =IF(AND(D14<D16,H14=H16),0,IF(AND(D14>D16,H14=H16),180,IF(AND(D14=D16,H14<H16),90,IF(AND(D14=D16,H14>H16),270,(ATAN(I15/J15)*180/PI()))))) -> #DIV/0! | L15: =IF(OR(K15=0,K15=90,K15=180,K15=270),K15,IF(AND(D14<D16,H14<H16),K15,IF(AND(D14<D16,H14>H16),360-K15,IF(AND(D14>D16,H14<H16),180-K15,IF(AND(D14>D16,H14>H16),180+K15))))) -> #DIV/0! | M15: =(IF(I15=0,G15,IF(G15=0,COS(D16*PI()/180)*I15,G15/COS(K15*PI()/180)))) -> 0 | N15: =IF(C17="","",ROUND(L15,1)) | O15: =IF(C17="","",ROUND(M15,1)) | T15: EVERY 5 MIN | V15: =(O15/P15+U15/60)/24 -> #VALUE!
A16: 2 | D16: =TRUNC(C16)+((C16-TRUNC(C16))/0.6) -> 0 | E16: =TRUNC(C17)+((C17-TRUNC(C17))/0.6) -> 0 | F16: =ROUND(((LOG10(TAN(PI()/4+(D16/2*PI()/180)))*7915.7046)-(3437.7468*((0.0816968^2*SIN(D16*PI()/180))+(0.0816968^4/3*((SIN(D16*PI()/180))^3))+(0.0816968^6/5*((SIN(D16*PI()/180))^5))))),2) -> 0 | H16: =IF(E16<0,E16+360,E16) -> 0 | Q16: =IF(O15="","",Q14+O15) | R16: =IF(O15="","",R14-O15) | T16: RADAR | W16: =IF(P15="","",W14+V15)
G17: =ABS(D16-D18)*60 -> 0 | I17: =ABS(H16-H18)*60 -> 0 | J17: =ABS(F16-F18) -> 0 | K17: =IF(AND(D16<D18,H16=H18),0,IF(AND(D16>D18,H16=H18),180,IF(AND(D16=D18,H16<H18),90,IF(AND(D16=D18,H16>H18),270,(ATAN(I17/J17)*180/PI()))))) -> #DIV/0! | L17: =IF(OR(K17=0,K17=90,K17=180,K17=270),K17,IF(AND(D16<D18,H16<H18),K17,IF(AND(D16<D18,H16>H18),360-K17,IF(AND(D16>D18,H16<H18),180-K17,IF(AND(D16>D18,H16>H18),180+K17))))) -> #DIV/0! | M17: =(IF(I17=0,G17,IF(G17=0,COS(D18*PI()/180)*I17,G17/COS(K17*PI()/180)))) -> 0 | N17: =IF(C19="","",ROUND(L17,1)) | O17: =IF(C19="","",ROUND(M17,1)) | T17: EVERY 5 MIN | V17: =(O17/P17+U17/60)/24 -> #VALUE!
A18: 3 | D18: =TRUNC(C18)+((C18-TRUNC(C18))/0.6) -> 0 | E18: =TRUNC(C19)+((C19-TRUNC(C19))/0.6) -> 0 | F18: =ROUND(((LOG10(TAN(PI()/4+(D18/2*PI()/180)))*7915.7046)-(3437.7468*((0.0816968^2*SIN(D18*PI()/180))+(0.0816968^4/3*((SIN(D18*PI()/180))^3))+(0.0816968^6/5*((SIN(D18*PI()/180))^5))))),2) -> 0 | H18: =IF(E18<0,E18+360,E18) -> 0 | Q18: =IF(O17="","",Q16+O17) | R18: =IF(O17="","",R16-O17) | T18: RADAR | W18: =IF(P17="","",W16+V17)
G19: =ABS(D18-D20)*60 -> 0 | I19: =ABS(H18-H20)*60 -> 0 | J19: =ABS(F18-F20) -> 0 | K19: =IF(AND(D18<D20,H18=H20),0,IF(AND(D18>D20,H18=H20),180,IF(AND(D18=D20,H18<H20),90,IF(AND(D18=D20,H18>H20),270,(ATAN(I19/J19)*180/PI()))))) -> #DIV/0! | L19: =IF(OR(K19=0,K19=90,K19=180,K19=270),K19,IF(AND(D18<D20,H18<H20),K19,IF(AND(D18<D20,H18>H20),360-K19,IF(AND(D18>D20,H18<H20),180-K19,IF(AND(D18>D20,H18>H20),180+K19))))) -> #DIV/0! | M19: =(IF(I19=0,G19,IF(G19=0,COS(D20*PI()/180)*I19,G19/COS(K19*PI()/180)))) -> 0 | N19: =IF(C21="","",ROUND(L19,1)) | O19: =IF(C21="","",ROUND(M19,1)) | T19: EVERY 5 MIN | V19: =(O19/P19+U19/60)/24 -> #VALUE!
A20: 4 | D20: =TRUNC(C20)+((C20-TRUNC(C20))/0.6) -> 0 | E20: =TRUNC(C21)+((C21-TRUNC(C21))/0.6) -> 0 | F20: =ROUND(((LOG10(TAN(PI()/4+(D20/2*PI()/180)))*7915.7046)-(3437.7468*((0.0816968^2*SIN(D20*PI()/180))+(0.0816968^4/3*((SIN(D20*PI()/180))^3))+(0.0816968^6/5*((SIN(D20*PI()/180))^5))))),2) -> 0 | H20: =IF(E20<0,E20+360,E20) -> 0 | Q20: =IF(O19="","",Q18+O19) | R20: =IF(O19="","",R18-O19) | T20: RADAR | W20: =IF(P19="","",W18+V19)
G21: =ABS(D20-D22)*60 -> 0 | I21: =ABS(H20-H22)*60 -> 0 | J21: =ABS(F20-F22) -> 0 | K21: =IF(AND(D20<D22,H20=H22),0,IF(AND(D20>D22,H20=H22),180,IF(AND(D20=D22,H20<H22),90,IF(AND(D20=D22,H20>H22),270,(ATAN(I21/J21)*180/PI()))))) -> #DIV/0! | L21: =IF(OR(K21=0,K21=90,K21=180,K21=270),K21,IF(AND(D20<D22,H20<H22),K21,IF(AND(D20<D22,H20>H22),360-K21,IF(AND(D20>D22,H20<H22),180-K21,IF(AND(D20>D22,H20>H22),180+K21))))) -> #DIV/0! | M21: =(IF(I21=0,G21,IF(G21=0,COS(D22*PI()/180)*I21,G21/COS(K21*PI()/180)))) -> 0 | N21: =IF(C23="","",ROUND(L21,1)) | O21: =IF(C23="","",ROUND(M21,1)) | T21: EVERY 5MIN. | V21: =(O21/P21+U21/60)/24 -> #VALUE!
A22: 5 | D22: =TRUNC(C22)+((C22-TRUNC(C22))/0.6) -> 0 | E22: =TRUNC(C23)+((C23-TRUNC(C23))/0.6) -> 0 | F22: =ROUND(((LOG10(TAN(PI()/4+(D22/2*PI()/180)))*7915.7046)-(3437.7468*((0.0816968^2*SIN(D22*PI()/180))+(0.0816968^4/3*((SIN(D22*PI()/180))^3))+(0.0816968^6/5*((SIN(D22*PI()/180))^5))))),2) -> 0 | H22: =IF(E22<0,E22+360,E22) -> 0 | Q22: =IF(O21="","",Q20+O21) | R22: =IF(O21="","",R20-O21) | T22: RADAR | W22: =IF(P21="","",W20+V21)
G23: =ABS(D22-D24)*60 -> 0 | I23: =ABS(H22-H24)*60 -> 0 | J23: =ABS(F22-F24) -> 0 | K23: =IF(AND(D22<D24,H22=H24),0,IF(AND(D22>D24,H22=H24),180,IF(AND(D22=D24,H22<H24),90,IF(AND(D22=D24,H22>H24),270,(ATAN(I23/J23)*180/PI()))))) -> #DIV/0! | L23: =IF(OR(K23=0,K23=90,K23=180,K23=270),K23,IF(AND(D22<D24,H22<H24),K23,IF(AND(D22<D24,H22>H24),360-K23,IF(AND(D22>D24,H22<H24),180-K23,IF(AND(D22>D24,H22>H24),180+K23))))) -> #DIV/0! | M23: =(IF(I23=0,G23,IF(G23=0,COS(D24*PI()/180)*I23,G23/COS(K23*PI()/180)))) -> 0 | N23: =IF(C25="","",ROUND(L23,1)) | O23: =IF(C25="","",ROUND(M23,1)) | T23: EVERY 5 MIN | V23: =(O23/P23+U23/60)/24 -> #VALUE!
A24: 6 | D24: =TRUNC(C24)+((C24-TRUNC(C24))/0.6) -> 0 | E24: =TRUNC(C25)+((C25-TRUNC(C25))/0.6) -> 0 | F24: =ROUND(((LOG10(TAN(PI()/4+(D24/2*PI()/180)))*7915.7046)-(3437.7468*((0.0816968^2*SIN(D24*PI()/180))+(0.0816968^4/3*((SIN(D24*PI()/180))^3))+(0.0816968^6/5*((SIN(D24*PI()/180))^5))))),2) -> 0 | H24: =IF(E24<0,E24+360,E24) -> 0 | Q24: =IF(O23="","",Q22+O23) | R24: =IF(O23="","",R22-O23) | T24: RADAR/GPS | W24: =IF(P23="","",W22+V23)
G25: =ABS(D24-D26)*60 -> 0 | I25: =ABS(H24-H26)*60 -> 0 | J25: =ABS(F24-F26) -> 0 | K25: =IF(AND(D24<D26,H24=H26),0,IF(AND(D24>D26,H24=H26),180,IF(AND(D24=D26,H24<H26),90,IF(AND(D24=D26,H24>H26),270,(ATAN(I25/J25)*180/PI()))))) -> #DIV/0! | L25: =IF(OR(K25=0,K25=90,K25=180,K25=270),K25,IF(AND(D24<D26,H24<H26),K25,IF(AND(D24<D26,H24>H26),360-K25,IF(AND(D24>D26,H24<H26),180-K25,IF(AND(D24>D26,H24>H26),180+K25))))) -> #DIV/0! | M25: =(IF(I25=0,G25,IF(G25=0,COS(D26*PI()/180)*I25,G25/COS(K25*PI()/180)))) -> 0 | N25: =IF(C27="","",ROUND(L25,1)) | O25: =IF(C27="","",ROUND(M25,1)) | T25: EVERY 5MIN. | V25: =(O25/P25+U25/60)/24 -> #VALUE!
A26: 7 | D26: =TRUNC(C26)+((C26-TRUNC(C26))/0.6) -> 0 | E26: =TRUNC(C27)+((C27-TRUNC(C27))/0.6) -> 0 | F26: =ROUND(((LOG10(TAN(PI()/4+(D26/2*PI()/180)))*7915.7046)-(3437.7468*((0.0816968^2*SIN(D26*PI()/180))+(0.0816968^4/3*((SIN(D26*PI()/180))^3))+(0.0816968^6/5*((SIN(D26*PI()/180))^5))))),2) -> 0 | H26: =IF(E26<0,E26+360,E26) -> 0 | Q26: =IF(O25="","",Q24+O25) | R26: =IF(O25="","",R24-O25) | T26: RADAR/GPS | W26: =IF(P25="","",W24+V25)
G27: =ABS(D26-D28)*60 -> 0 | I27: =ABS(H26-H28)*60 -> 0 | J27: =ABS(F26-F28) -> 0 | K27: =IF(AND(D26<D28,H26=H28),0,IF(AND(D26>D28,H26=H28),180,IF(AND(D26=D28,H26<H28),90,IF(AND(D26=D28,H26>H28),270,(ATAN(I27/J27)*180/PI()))))) -> #DIV/0! | L27: =IF(OR(K27=0,K27=90,K27=180,K27=270),K27,IF(AND(D26<D28,H26<H28),K27,IF(AND(D26<D28,H26>H28),360-K27,IF(AND(D26>D28,H26<H28),180-K27,IF(AND(D26>D28,H26>H28),180+K27))))) -> #DIV/0! | M27: =(IF(I27=0,G27,IF(G27=0,COS(D28*PI()/180)*I27,G27/COS(K27*PI()/180)))) -> 0 | N27: =IF(C29="","",ROUND(L27,1)) | O27: =IF(C29="","",ROUND(M27,1)) | T27: EVERY 5MIN. | V27: =(O27/P27+U27/60)/24 -> #VALUE!
A28: 8 | D28: =TRUNC(C28)+((C28-TRUNC(C28))/0.6) -> 0 | E28: =TRUNC(C29)+((C29-TRUNC(C29))/0.6) -> 0 | F28: =ROUND(((LOG10(TAN(PI()/4+(D28/2*PI()/180)))*7915.7046)-(3437.7468*((0.0816968^2*SIN(D28*PI()/180))+(0.0816968^4/3*((SIN(D28*PI()/180))^3))+(0.0816968^6/5*((SIN(D28*PI()/180))^5))))),2) -> 0 | H28: =IF(E28<0,E28+360,E28) -> 0 | Q28: =IF(O27="","",Q26+O27) | R28: =IF(O27="","",R26-O27) | T28: RADR/GPS | W28: =IF(P27="","",W26+V27)
G29: =ABS(D28-D30)*60 -> 0 | I29: =ABS(H28-H30)*60 -> 0 | J29: =ABS(F28-F30) -> 0 | K29: =IF(AND(D28<D30,H28=H30),0,IF(AND(D28>D30,H28=H30),180,IF(AND(D28=D30,H28<H30),90,IF(AND(D28=D30,H28>H30),270,(ATAN(I29/J29)*180/PI()))))) -> #DIV/0! | L29: =IF(OR(K29=0,K29=90,K29=180,K29=270),K29,IF(AND(D28<D30,H28<H30),K29,IF(AND(D28<D30,H28>H30),360-K29,IF(AND(D28>D30,H28<H30),180-K29,IF(AND(D28>D30,H28>H30),180+K29))))) -> #DIV/0! | M29: =(IF(I29=0,G29,IF(G29=0,COS(D30*PI()/180)*I29,G29/COS(K29*PI()/180)))) -> 0 | N29: =IF(C31="","",ROUND(L29,1)) | O29: =IF(C31="","",ROUND(M29,1)) | T29: EVERY 5MIN. | V29: =(O29/P29+U29/60)/24 -> #VALUE!
A30: 9 | D30: =TRUNC(C30)+((C30-TRUNC(C30))/0.6) -> 0 | E30: =TRUNC(C31)+((C31-TRUNC(C31))/0.6) -> 0 | F30: =ROUND(((LOG10(TAN(PI()/4+(D30/2*PI()/180)))*7915.7046)-(3437.7468*((0.0816968^2*SIN(D30*PI()/180))+(0.0816968^4/3*((SIN(D30*PI()/180))^3))+(0.0816968^6/5*((SIN(D30*PI()/180))^5))))),2) -> 0 | H30: =IF(E30<0,E30+360,E30) -> 0 | Q30: =IF(O29="","",Q28+O29) | R30: =IF(O29="","",R28-O29) | T30: RADAR/GPS | W30: =IF(P29="","",W28+V29)
G31: =ABS(D30-D32)*60 -> 0 | I31: =ABS(H30-H32)*60 -> 0 | J31: =ABS(F30-F32) -> 0 | K31: =IF(AND(D30<D32,H30=H32),0,IF(AND(D30>D32,H30=H32),180,IF(AND(D30=D32,H30<H32),90,IF(AND(D30=D32,H30>H32),270,(ATAN(I31/J31)*180/PI()))))) -> #DIV/0! | L31: =IF(OR(K31=0,K31=90,K31=180,K31=270),K31,IF(AND(D30<D32,H30<H32),K31,IF(AND(D30<D32,H30>H32),360-K31,IF(AND(D30>D32,H30<H32),180-K31,IF(AND(D30>D32,H30>H32),180+K31))))) -> #DIV/0! | M31: =(IF(I31=0,G31,IF(G31=0,COS(D32*PI()/180)*I31,G31/COS(K31*PI()/180)))) -> 0 | N31: =IF(C33="","",ROUND(L31,1)) | O31: =IF(C33="","",ROUND(M31,1)) | T31: EVERY 5 MIN | V31: =(O31/P31+U31/60)/24 -> #VALUE!
A32: 10 | D32: =TRUNC(C32)+((C32-TRUNC(C32))/0.6) -> 0 | E32: =TRUNC(C33)+((C33-TRUNC(C33))/0.6) -> 0 | F32: =ROUND(((LOG10(TAN(PI()/4+(D32/2*PI()/180)))*7915.7046)-(3437.7468*((0.0816968^2*SIN(D32*PI()/180))+(0.0816968^4/3*((SIN(D32*PI()/180))^3))+(0.0816968^6/5*((SIN(D32*PI()/180))^5))))),2) -> 0 | H32: =IF(E32<0,E32+360,E32) -> 0 | Q32: =IF(O31="","",Q30+O31) | R32: =IF(O31="","",R30-O31) | T32: RADAR/GPS | W32: =IF(P31="","",W30+V31)
G33: =ABS(D32-D34)*60 -> 0 | I33: =ABS(H32-H34)*60 -> 0 | J33: =ABS(F32-F34) -> 0 | K33: =IF(AND(D32<D34,H32=H34),0,IF(AND(D32>D34,H32=H34),180,IF(AND(D32=D34,H32<H34),90,IF(AND(D32=D34,H32>H34),270,(ATAN(I33/J33)*180/PI()))))) -> #DIV/0! | L33: =IF(OR(K33=0,K33=90,K33=180,K33=270),K33,IF(AND(D32<D34,H32<H34),K33,IF(AND(D32<D34,H32>H34),360-K33,IF(AND(D32>D34,H32<H34),180-K33,IF(AND(D32>D34,H32>H34),180+K33))))) -> #DIV/0! | M33: =(IF(I33=0,G33,IF(G33=0,COS(D34*PI()/180)*I33,G33/COS(K33*PI()/180)))) -> 0 | N33: =IF(C35="","",ROUND(L33,1)) | O33: =IF(C35="","",ROUND(M33,1)) | T33: EVERY 15 MIN | V33: =(O33/P33+U33/60)/24 -> #VALUE!
A34: 11 | D34: =TRUNC(C34)+((C34-TRUNC(C34))/0.6) -> 0 | E34: =TRUNC(C35)+((C35-TRUNC(C35))/0.6) -> 0 | F34: =ROUND(((LOG10(TAN(PI()/4+(D34/2*PI()/180)))*7915.7046)-(3437.7468*((0.0816968^2*SIN(D34*PI()/180))+(0.0816968^4/3*((SIN(D34*PI()/180))^3))+(0.0816968^6/5*((SIN(D34*PI()/180))^5))))),2) -> 0 | H34: =IF(E34<0,E34+360,E34) -> 0 | Q34: =IF(O33="","",Q32+O33) | R34: =IF(O33="","",R32-O33) | T34: RADAR/GPS | W34: =IF(P33="","",W32+V33)
G35: =ABS(D34-D36)*60 -> 0 | I35: =ABS(H34-H36)*60 -> 0 | J35: =ABS(F34-F36) -> 0 | K35: =IF(AND(D34<D36,H34=H36),0,IF(AND(D34>D36,H34=H36),180,IF(AND(D34=D36,H34<H36),90,IF(AND(D34=D36,H34>H36),270,(ATAN(I35/J35)*180/PI()))))) -> #DIV/0! | L35: =IF(OR(K35=0,K35=90,K35=180,K35=270),K35,IF(AND(D34<D36,H34<H36),K35,IF(AND(D34<D36,H34>H36),360-K35,IF(AND(D34>D36,H34<H36),180-K35,IF(AND(D34>D36,H34>H36),180+K35))))) -> #DIV/0! | M35: =(IF(I35=0,G35,IF(G35=0,COS(D36*PI()/180)*I35,G35/COS(K35*PI()/180)))) -> 0 | N35: =IF(C37="","",ROUND(L35,1)) | O35: =IF(C37="","",ROUND(M35,1)) | T35: EVERY 15 MIN | V35: =(O35/P35+U35/60)/24 -> #VALUE!
A36: 12 | D36: =TRUNC(C36)+((C36-TRUNC(C36))/0.6) -> 0 | E36: =TRUNC(C37)+((C37-TRUNC(C37))/0.6) -> 0 | F36: =ROUND(((LOG10(TAN(PI()/4+(D36/2*PI()/180)))*7915.7046)-(3437.7468*((0.0816968^2*SIN(D36*PI()/180))+(0.0816968^4/3*((SIN(D36*PI()/180))^3))+(0.0816968^6/5*((SIN(D36*PI()/180))^5))))),2) -> 0 | H36: =IF(E36<0,E36+360,E36) -> 0 | Q36: =IF(O35="","",Q34+O35) | R36: =IF(O35="","",R34-O35) | T36: RADAR/GPS | W36: =IF(P35="","",W34+V35)
G37: =ABS(D36-D38)*60 -> 0 | I37: =ABS(H36-H38)*60 -> 0 | J37: =ABS(F36-F38) -> 0 | K37: =IF(AND(D36<D38,H36=H38),0,IF(AND(D36>D38,H36=H38),180,IF(AND(D36=D38,H36<H38),90,IF(AND(D36=D38,H36>H38),270,(ATAN(I37/J37)*180/PI()))))) -> #DIV/0! | L37: =IF(OR(K37=0,K37=90,K37=180,K37=270),K37,IF(AND(D36<D38,H36<H38),K37,IF(AND(D36<D38,H36>H38),360-K37,IF(AND(D36>D38,H36<H38),180-K37,IF(AND(D36>D38,H36>H38),180+K37))))) -> #DIV/0! | M37: =(IF(I37=0,G37,IF(G37=0,COS(D38*PI()/180)*I37,G37/COS(K37*PI()/180)))) -> 0 | N37: =IF(C39="","",ROUND(L37,1)) | O37: =IF(C39="","",ROUND(M37,1)) | T37: EVERY 30 MIN | V37: =(O37/P37+U37/60)/24 -> #VALUE!
A38: 13 | D38: =TRUNC(C38)+((C38-TRUNC(C38))/0.6) -> 0 | E38: =TRUNC(C39)+((C39-TRUNC(C39))/0.6) -> 0 | F38: =ROUND(((LOG10(TAN(PI()/4+(D38/2*PI()/180)))*7915.7046)-(3437.7468*((0.0816968^2*SIN(D38*PI()/180))+(0.0816968^4/3*((SIN(D38*PI()/180))^3))+(0.0816968^6/5*((SIN(D38*PI()/180))^5))))),2) -> 0 | H38: =IF(E38<0,E38+360,E38) -> 0 | Q38: =IF(O37="","",Q36+O37) | R38: =IF(O37="","",R36-O37) | T38: RADAR/GPS | W38: =IF(P37="","",W36+V37)
G39: =ABS(D38-D40)*60 -> 0 | I39: =ABS(H38-H40)*60 -> 0 | J39: =ABS(F38-F40) -> 0 | K39: =IF(AND(D38<D40,H38=H40),0,IF(AND(D38>D40,H38=H40),180,IF(AND(D38=D40,H38<H40),90,IF(AND(D38=D40,H38>H40),270,(ATAN(I39/J39)*180/PI()))))) -> #DIV/0! | L39: =IF(OR(K39=0,K39=90,K39=180,K39=270),K39,IF(AND(D38<D40,H38<H40),K39,IF(AND(D38<D40,H38>H40),360-K39,IF(AND(D38>D40,H38<H40),180-K39,IF(AND(D38>D40,H38>H40),180+K39))))) -> #DIV/0! | M39: =(IF(I39=0,G39,IF(G39=0,COS(D40*PI()/180)*I39,G39/COS(K39*PI()/180)))) -> 0 | N39: =IF(C41="","",ROUND(L39,1)) | O39: =IF(C41="","",ROUND(M39,1)) | T39: EVERY 30 MIN | V39: =(O39/P39+U39/60)/24 -> #VALUE!
A40: 14 | D40: =TRUNC(C40)+((C40-TRUNC(C40))/0.6) -> 0 | E40: =TRUNC(C41)+((C41-TRUNC(C41))/0.6) -> 0 | F40: =ROUND(((LOG10(TAN(PI()/4+(D40/2*PI()/180)))*7915.7046)-(3437.7468*((0.0816968^2*SIN(D40*PI()/180))+(0.0816968^4/3*((SIN(D40*PI()/180))^3))+(0.0816968^6/5*((SIN(D40*PI()/180))^5))))),2) -> 0 | H40: =IF(E40<0,E40+360,E40) -> 0 | Q40: =IF(O39="","",Q38+O39) | R40: =IF(O39="","",R38-O39) | T40: GPS | W40: =IF(P39="","",W38+V39)
G41: =ABS(D40-D42)*60 -> 0 | I41: =ABS(H40-H42)*60 -> 0 | J41: =ABS(F40-F42) -> 0 | K41: =IF(AND(D40<D42,H40=H42),0,IF(AND(D40>D42,H40=H42),180,IF(AND(D40=D42,H40<H42),90,IF(AND(D40=D42,H40>H42),270,(ATAN(I41/J41)*180/PI()))))) -> #DIV/0! | L41: =IF(OR(K41=0,K41=90,K41=180,K41=270),K41,IF(AND(D40<D42,H40<H42),K41,IF(AND(D40<D42,H40>H42),360-K41,IF(AND(D40>D42,H40<H42),180-K41,IF(AND(D40>D42,H40>H42),180+K41))))) -> #DIV/0! | M41: =(IF(I41=0,G41,IF(G41=0,COS(D42*PI()/180)*I41,G41/COS(K41*PI()/180)))) -> 0 | N41: =IF(C43="","",ROUND(L41,1)) | O41: =IF(C43="","",ROUND(M41,1)) | T41: EVERY 1 HR. | V41: =(O41/P41+U41/60)/24 -> #VALUE!
...

Sheet  ARRIVAL - Pilot to Berth
A1: PIMSAT COLLEGES, INC. McArthur Highway, Bolosan District, Dagupan City COLLEGE OF MARITIME EDUCATION Bachelor of Science in Marine Transportation
A2: NAV 7 - VOYAGE PLANNING
A4: YEAR & SECTION: | C4: ='FRONT PAGE'!C28 -> 0 | Q4: MEMBERS: | U4: 1 | W4: ='FRONT PAGE'!H28 -> 0 | AA4: 3 | AB4: ='FRONT PAGE'!M28 -> 0
A5: GROUP NO: | C5: ='FRONT PAGE'!C29 -> 0 | U5: 2 | W5: ='FRONT PAGE'!H29 -> 0 | AA5: 4 | AB5: ='FRONT PAGE'!M29 -> 0
A6: ARRIVAL PORT - Passage from Pilot Station to Berth
A7: NAME OF VESSEL: | C7: ='FRONT PAGE'!F21 -> 0 | P7: DEPARTURE: | R7: ='FRONT PAGE'!C25 -> 0 | U7: ARRIVAL: | X7: ='FRONT PAGE'!J25 -> 0 | Z7: VOYAGE NO: | AB7: ='FRONT PAGE'!H23 -> 0
A8: NO. | B8: NAME/ REFERENCE | C8: POSITION | N8: T/CO | O8: DIST | P8: SP'D | Q8: F'M | R8: TO | S8: ESTIMATED MINIMUM UKC / E (ENOUGH) | T8: POSITION | U8: TIME CORR. (min.) | W8: ETA/ETP (L.T.) DD/MM/YY | X8: METHODS OF OBTAINING POSITION | Y8: POSITION FIXING INTERVAL | Z8: CALL MASTER | AA8: WATCH LEVEL | AB8: CHART NO. | AC8: GARBAGE/SEWAGE DISPOSAL | AD8: REMARKS:
T9: FIX SYSTEM
D10: Lat | E10: Long | F10: 漸長緯度 | G10: 緯差 | H10: Long (360) | I10: 経差 | J10: 漸長緯度差 | L10: 針路 | M10: 距離 | T10: PRIMARY
T11: SECONDARY
A12: 0 | D12: =TRUNC(C12)+((C12-TRUNC(C12))/0.6) -> 0 | E12: =TRUNC(C13)+((C13-TRUNC(C13))/0.6) -> 0 | F12: =ROUND(((LOG10(TAN(PI()/4+(D12/2*PI()/180)))*7915.7046)-(3437.7468*((0.0816968^2*SIN(D12*PI()/180))+(0.0816968^4/3*((SIN(D12*PI()/180))^3))+(0.0816968^6/5*((SIN(D12*PI()/180))^5))))),2) -> 0 | H12: =IF(E12<0,E12+360,E12) -> 0 | Q12: 0 | T12: RADAR | W12: 45982.208
G13: =ABS(D12-D14)*60 -> 0 | I13: =ABS(H12-H14)*60 -> 0 | J13: =ABS(F12-F14) -> 0 | K13: =IF(AND(D12<D14,H12=H14),0,IF(AND(D12>D14,H12=H14),180,IF(AND(D12=D14,H12<H14),90,IF(AND(D12=D14,H12>H14),270,(ATAN(I13/J13)*180/PI()))))) -> #DIV/0! | L13: =IF(OR(K13=0,K13=90,K13=180,K13=270),K13,IF(AND(D12<D14,H12<H14),K13,IF(AND(D12<D14,H12>H14),360-K13,IF(AND(D12>D14,H12<H14),180-K13,IF(AND(D12>D14,H12>H14),180+K13))))) -> #DIV/0! | M13: =(IF(I13=0,G13,IF(G13=0,COS(D14*PI()/180)*I13,G13/COS(K13*PI()/180)))) -> 0 | N13: =IF(C15="","",ROUND(L13,1)) | O13: =IF(C15="","",ROUND(M13,1)) | T13: EVERY 5 MIN | V13: =(O13/P13+U13/60)/24 -> #VALUE!
A14: 1 | D14: =TRUNC(C14)+((C14-TRUNC(C14))/0.6) -> 0 | E14: =TRUNC(C15)+((C15-TRUNC(C15))/0.6) -> 0 | F14: =ROUND(((LOG10(TAN(PI()/4+(D14/2*PI()/180)))*7915.7046)-(3437.7468*((0.0816968^2*SIN(D14*PI()/180))+(0.0816968^4/3*((SIN(D14*PI()/180))^3))+(0.0816968^6/5*((SIN(D14*PI()/180))^5))))),2) -> 0 | H14: =IF(E14<0,E14+360,E14) -> 0 | Q14: =IF(O13="","",Q12+O13) | R14: =IF(O13="","",R12-O13) | T14: RADAR | W14: =IF(P13="","",W12+V13)
G15: =ABS(D14-D16)*60 -> 0 | I15: =ABS(H14-H16)*60 -> 0 | J15: =ABS(F14-F16) -> 0 | K15: =IF(AND(D14<D16,H14=H16),0,IF(AND(D14>D16,H14=H16),180,IF(AND(D14=D16,H14<H16),90,IF(AND(D14=D16,H14>H16),270,(ATAN(I15/J15)*180/PI()))))) -> #DIV/0! | L15: =IF(OR(K15=0,K15=90,K15=180,K15=270),K15,IF(AND(D14<D16,H14<H16),K15,IF(AND(D14<D16,H14>H16),360-K15,IF(AND(D14>D16,H14<H16),180-K15,IF(AND(D14>D16,H14>H16),180+K15))))) -> #DIV/0! | M15: =(IF(I15=0,G15,IF(G15=0,COS(D16*PI()/180)*I15,G15/COS(K15*PI()/180)))) -> 0 | N15: =IF(C17="","",ROUND(L15,1)) | O15: =IF(C17="","",ROUND(M15,1)) | T15: EVERY 5 MIN | V15: =(O15/P15+U15/60)/24 -> #VALUE!
A16: 2 | D16: =TRUNC(C16)+((C16-TRUNC(C16))/0.6) -> 0 | E16: =TRUNC(C17)+((C17-TRUNC(C17))/0.6) -> 0 | F16: =ROUND(((LOG10(TAN(PI()/4+(D16/2*PI()/180)))*7915.7046)-(3437.7468*((0.0816968^2*SIN(D16*PI()/180))+(0.0816968^4/3*((SIN(D16*PI()/180))^3))+(0.0816968^6/5*((SIN(D16*PI()/180))^5))))),2) -> 0 | H16: =IF(E16<0,E16+360,E16) -> 0 | Q16: =IF(O15="","",Q14+O15) | R16: =IF(O15="","",R14-O15) | T16: RADAR | W16: =IF(P15="","",W14+V15)
G17: =ABS(D16-D18)*60 -> 0 | I17: =ABS(H16-H18)*60 -> 0 | J17: =ABS(F16-F18) -> 0 | K17: =IF(AND(D16<D18,H16=H18),0,IF(AND(D16>D18,H16=H18),180,IF(AND(D16=D18,H16<H18),90,IF(AND(D16=D18,H16>H18),270,(ATAN(I17/J17)*180/PI()))))) -> #DIV/0! | L17: =IF(OR(K17=0,K17=90,K17=180,K17=270),K17,IF(AND(D16<D18,H16<H18),K17,IF(AND(D16<D18,H16>H18),360-K17,IF(AND(D16>D18,H16<H18),180-K17,IF(AND(D16>D18,H16>H18),180+K17))))) -> #DIV/0! | M17: =(IF(I17=0,G17,IF(G17=0,COS(D18*PI()/180)*I17,G17/COS(K17*PI()/180)))) -> 0 | N17: =IF(C19="","",ROUND(L17,1)) | O17: =IF(C19="","",ROUND(M17,1)) | T17: EVERY 5 MIN | V17: =(O17/P17+U17/60)/24 -> #VALUE!
A18: 3 | D18: =TRUNC(C18)+((C18-TRUNC(C18))/0.6) -> 0 | E18: =TRUNC(C19)+((C19-TRUNC(C19))/0.6) -> 0 | F18: =ROUND(((LOG10(TAN(PI()/4+(D18/2*PI()/180)))*7915.7046)-(3437.7468*((0.0816968^2*SIN(D18*PI()/180))+(0.0816968^4/3*((SIN(D18*PI()/180))^3))+(0.0816968^6/5*((SIN(D18*PI()/180))^5))))),2) -> 0 | H18: =IF(E18<0,E18+360,E18) -> 0 | Q18: =IF(O17="","",Q16+O17) | R18: =IF(O17="","",R16-O17) | T18: RADAR | W18: =IF(P17="","",W16+V17)
G19: =ABS(D18-D20)*60 -> 0 | I19: =ABS(H18-H20)*60 -> 0 | J19: =ABS(F18-F20) -> 0 | K19: =IF(AND(D18<D20,H18=H20),0,IF(AND(D18>D20,H18=H20),180,IF(AND(D18=D20,H18<H20),90,IF(AND(D18=D20,H18>H20),270,(ATAN(I19/J19)*180/PI()))))) -> #DIV/0! | L19: =IF(OR(K19=0,K19=90,K19=180,K19=270),K19,IF(AND(D18<D20,H18<H20),K19,IF(AND(D18<D20,H18>H20),360-K19,IF(AND(D18>D20,H18<H20),180-K19,IF(AND(D18>D20,H18>H20),180+K19))))) -> #DIV/0! | M19: =(IF(I19=0,G19,IF(G19=0,COS(D20*PI()/180)*I19,G19/COS(K19*PI()/180)))) -> 0 | N19: =IF(C21="","",ROUND(L19,1)) | O19: =IF(C21="","",ROUND(M19,1)) | T19: EVERY 5 MIN | V19: =(O19/P19+U19/60)/24 -> #VALUE!
A20: 4 | D20: =TRUNC(C20)+((C20-TRUNC(C20))/0.6) -> 0 | E20: =TRUNC(C21)+((C21-TRUNC(C21))/0.6) -> 0 | F20: =ROUND(((LOG10(TAN(PI()/4+(D20/2*PI()/180)))*7915.7046)-(3437.7468*((0.0816968^2*SIN(D20*PI()/180))+(0.0816968^4/3*((SIN(D20*PI()/180))^3))+(0.0816968^6/5*((SIN(D20*PI()/180))^5))))),2) -> 0 | H20: =IF(E20<0,E20+360,E20) -> 0 | Q20: =IF(O19="","",Q18+O19) | R20: =IF(O19="","",R18-O19) | T20: RADAR | W20: =IF(P19="","",W18+V19)
G21: =ABS(D20-D22)*60 -> 0 | I21: =ABS(H20-H22)*60 -> 0 | J21: =ABS(F20-F22) -> 0 | K21: =IF(AND(D20<D22,H20=H22),0,IF(AND(D20>D22,H20=H22),180,IF(AND(D20=D22,H20<H22),90,IF(AND(D20=D22,H20>H22),270,(ATAN(I21/J21)*180/PI()))))) -> #DIV/0! | L21: =IF(OR(K21=0,K21=90,K21=180,K21=270),K21,IF(AND(D20<D22,H20<H22),K21,IF(AND(D20<D22,H20>H22),360-K21,IF(AND(D20>D22,H20<H22),180-K21,IF(AND(D20>D22,H20>H22),180+K21))))) -> #DIV/0! | M21: =(IF(I21=0,G21,IF(G21=0,COS(D22*PI()/180)*I21,G21/COS(K21*PI()/180)))) -> 0 | N21: =IF(C23="","",ROUND(L21,1)) | O21: =IF(C23="","",ROUND(M21,1)) | T21: EVERY 5MIN. | V21: =(O21/P21+U21/60)/24 -> #VALUE!
A22: 5 | D22: =TRUNC(C22)+((C22-TRUNC(C22))/0.6) -> 0 | E22: =TRUNC(C23)+((C23-TRUNC(C23))/0.6) -> 0 | F22: =ROUND(((LOG10(TAN(PI()/4+(D22/2*PI()/180)))*7915.7046)-(3437.7468*((0.0816968^2*SIN(D22*PI()/180))+(0.0816968^4/3*((SIN(D22*PI()/180))^3))+(0.0816968^6/5*((SIN(D22*PI()/180))^5))))),2) -> 0 | H22: =IF(E22<0,E22+360,E22) -> 0 | Q22: =IF(O21="","",Q20+O21) | R22: =IF(O21="","",R20-O21) | T22: RADAR | W22: =IF(P21="","",W20+V21)
G23: =ABS(D22-D24)*60 -> 0 | I23: =ABS(H22-H24)*60 -> 0 | J23: =ABS(F22-F24) -> 0 | K23: =IF(AND(D22<D24,H22=H24),0,IF(AND(D22>D24,H22=H24),180,IF(AND(D22=D24,H22<H24),90,IF(AND(D22=D24,H22>H24),270,(ATAN(I23/J23)*180/PI()))))) -> #DIV/0! | L23: =IF(OR(K23=0,K23=90,K23=180,K23=270),K23,IF(AND(D22<D24,H22<H24),K23,IF(AND(D22<D24,H22>H24),360-K23,IF(AND(D22>D24,H22<H24),180-K23,IF(AND(D22>D24,H22>H24),180+K23))))) -> #DIV/0! | M23: =(IF(I23=0,G23,IF(G23=0,COS(D24*PI()/180)*I23,G23/COS(K23*PI()/180)))) -> 0 | N23: =IF(C25="","",ROUND(L23,1)) | O23: =IF(C25="","",ROUND(M23,1)) | T23: EVERY 5 MIN | V23: =(O23/P23+U23/60)/24 -> #VALUE!
A24: 6 | D24: =TRUNC(C24)+((C24-TRUNC(C24))/0.6) -> 0 | E24: =TRUNC(C25)+((C25-TRUNC(C25))/0.6) -> 0 | F24: =ROUND(((LOG10(TAN(PI()/4+(D24/2*PI()/180)))*7915.7046)-(3437.7468*((0.0816968^2*SIN(D24*PI()/180))+(0.0816968^4/3*((SIN(D24*PI()/180))^3))+(0.0816968^6/5*((SIN(D24*PI()/180))^5))))),2) -> 0 | H24: =IF(E24<0,E24+360,E24) -> 0 | Q24: =IF(O23="","",Q22+O23) | R24: =IF(O23="","",R22-O23) | T24: RADAR/GPS | W24: =IF(P23="","",W22+V23)
G25: =ABS(D24-D26)*60 -> 0 | I25: =ABS(H24-H26)*60 -> 0 | J25: =ABS(F24-F26) -> 0 | K25: =IF(AND(D24<D26,H24=H26),0,IF(AND(D24>D26,H24=H26),180,IF(AND(D24=D26,H24<H26),90,IF(AND(D24=D26,H24>H26),270,(ATAN(I25/J25)*180/PI()))))) -> #DIV/0! | L25: =IF(OR(K25=0,K25=90,K25=180,K25=270),K25,IF(AND(D24<D26,H24<H26),K25,IF(AND(D24<D26,H24>H26),360-K25,IF(AND(D24>D26,H24<H26),180-K25,IF(AND(D24>D26,H24>H26),180+K25))))) -> #DIV/0! | M25: =(IF(I25=0,G25,IF(G25=0,COS(D26*PI()/180)*I25,G25/COS(K25*PI()/180)))) -> 0 | N25: =IF(C27="","",ROUND(L25,1)) | O25: =IF(C27="","",ROUND(M25,1)) | T25: EVERY 5MIN. | V25: =(O25/P25+U25/60)/24 -> #VALUE!
A26: 7 | D26: =TRUNC(C26)+((C26-TRUNC(C26))/0.6) -> 0 | E26: =TRUNC(C27)+((C27-TRUNC(C27))/0.6) -> 0 | F26: =ROUND(((LOG10(TAN(PI()/4+(D26/2*PI()/180)))*7915.7046)-(3437.7468*((0.0816968^2*SIN(D26*PI()/180))+(0.0816968^4/3*((SIN(D26*PI()/180))^3))+(0.0816968^6/5*((SIN(D26*PI()/180))^5))))),2) -> 0 | H26: =IF(E26<0,E26+360,E26) -> 0 | Q26: =IF(O25="","",Q24+O25) | R26: =IF(O25="","",R24-O25) | T26: RADAR/GPS | W26: =IF(P25="","",W24+V25)
G27: =ABS(D26-D28)*60 -> 0 | I27: =ABS(H26-H28)*60 -> 0 | J27: =ABS(F26-F28) -> 0 | K27: =IF(AND(D26<D28,H26=H28),0,IF(AND(D26>D28,H26=H28),180,IF(AND(D26=D28,H26<H28),90,IF(AND(D26=D28,H26>H28),270,(ATAN(I27/J27)*180/PI()))))) -> #DIV/0! | L27: =IF(OR(K27=0,K27=90,K27=180,K27=270),K27,IF(AND(D26<D28,H26<H28),K27,IF(AND(D26<D28,H26>H28),360-K27,IF(AND(D26>D28,H26<H28),180-K27,IF(AND(D26>D28,H26>H28),180+K27))))) -> #DIV/0! | M27: =(IF(I27=0,G27,IF(G27=0,COS(D28*PI()/180)*I27,G27/COS(K27*PI()/180)))) -> 0 | N27: =IF(C29="","",ROUND(L27,1)) | O27: =IF(C29="","",ROUND(M27,1)) | T27: EVERY 5MIN. | V27: =(O27/P27+U27/60)/24 -> #VALUE!
A28: 8 | D28: =TRUNC(C28)+((C28-TRUNC(C28))/0.6) -> 0 | E28: =TRUNC(C29)+((C29-TRUNC(C29))/0.6) -> 0 | F28: =ROUND(((LOG10(TAN(PI()/4+(D28/2*PI()/180)))*7915.7046)-(3437.7468*((0.0816968^2*SIN(D28*PI()/180))+(0.0816968^4/3*((SIN(D28*PI()/180))^3))+(0.0816968^6/5*((SIN(D28*PI()/180))^5))))),2) -> 0 | H28: =IF(E28<0,E28+360,E28) -> 0 | Q28: =IF(O27="","",Q26+O27) | R28: =IF(O27="","",R26-O27) | T28: RADR/GPS | W28: =IF(P27="","",W26+V27)
G29: =ABS(D28-D30)*60 -> 0 | I29: =ABS(H28-H30)*60 -> 0 | J29: =ABS(F28-F30) -> 0 | K29: =IF(AND(D28<D30,H28=H30),0,IF(AND(D28>D30,H28=H30),180,IF(AND(D28=D30,H28<H30),90,IF(AND(D28=D30,H28>H30),270,(ATAN(I29/J29)*180/PI()))))) -> #DIV/0! | L29: =IF(OR(K29=0,K29=90,K29=180,K29=270),K29,IF(AND(D28<D30,H28<H30),K29,IF(AND(D28<D30,H28>H30),360-K29,IF(AND(D28>D30,H28<H30),180-K29,IF(AND(D28>D30,H28>H30),180+K29))))) -> #DIV/0! | M29: =(IF(I29=0,G29,IF(G29=0,COS(D30*PI()/180)*I29,G29/COS(K29*PI()/180)))) -> 0 | N29: =IF(C31="","",ROUND(L29,1)) | O29: =IF(C31="","",ROUND(M29,1)) | T29: EVERY 5MIN. | V29: =(O29/P29+U29/60)/24 -> #VALUE!
A30: 9 | D30: =TRUNC(C30)+((C30-TRUNC(C30))/0.6) -> 0 | E30: =TRUNC(C31)+((C31-TRUNC(C31))/0.6) -> 0 | F30: =ROUND(((LOG10(TAN(PI()/4+(D30/2*PI()/180)))*7915.7046)-(3437.7468*((0.0816968^2*SIN(D30*PI()/180))+(0.0816968^4/3*((SIN(D30*PI()/180))^3))+(0.0816968^6/5*((SIN(D30*PI()/180))^5))))),2) -> 0 | H30: =IF(E30<0,E30+360,E30) -> 0 | Q30: =IF(O29="","",Q28+O29) | R30: =IF(O29="","",R28-O29) | T30: RADAR/GPS | W30: =IF(P29="","",W28+V29)
G31: =ABS(D30-D32)*60 -> 0 | I31: =ABS(H30-H32)*60 -> 0 | J31: =ABS(F30-F32) -> 0 | K31: =IF(AND(D30<D32,H30=H32),0,IF(AND(D30>D32,H30=H32),180,IF(AND(D30=D32,H30<H32),90,IF(AND(D30=D32,H30>H32),270,(ATAN(I31/J31)*180/PI()))))) -> #DIV/0! | L31: =IF(OR(K31=0,K31=90,K31=180,K31=270),K31,IF(AND(D30<D32,H30<H32),K31,IF(AND(D30<D32,H30>H32),360-K31,IF(AND(D30>D32,H30<H32),180-K31,IF(AND(D30>D32,H30>H32),180+K31))))) -> #DIV/0! | M31: =(IF(I31=0,G31,IF(G31=0,COS(D32*PI()/180)*I31,G31/COS(K31*PI()/180)))) -> 0 | N31: =IF(C33="","",ROUND(L31,1)) | O31: =IF(C33="","",ROUND(M31,1)) | T31: EVERY 5 MIN | V31: =(O31/P31+U31/60)/24 -> #VALUE!
A32: 10 | D32: =TRUNC(C32)+((C32-TRUNC(C32))/0.6) -> 0 | E32: =TRUNC(C33)+((C33-TRUNC(C33))/0.6) -> 0 | F32: =ROUND(((LOG10(TAN(PI()/4+(D32/2*PI()/180)))*7915.7046)-(3437.7468*((0.0816968^2*SIN(D32*PI()/180))+(0.0816968^4/3*((SIN(D32*PI()/180))^3))+(0.0816968^6/5*((SIN(D32*PI()/180))^5))))),2) -> 0 | H32: =IF(E32<0,E32+360,E32) -> 0 | Q32: =IF(O31="","",Q30+O31) | R32: =IF(O31="","",R30-O31) | T32: RADAR/GPS | W32: =IF(P31="","",W30+V31)
G33: =ABS(D32-D34)*60 -> 0 | I33: =ABS(H32-H34)*60 -> 0 | J33: =ABS(F32-F34) -> 0 | K33: =IF(AND(D32<D34,H32=H34),0,IF(AND(D32>D34,H32=H34),180,IF(AND(D32=D34,H32<H34),90,IF(AND(D32=D34,H32>H34),270,(ATAN(I33/J33)*180/PI()))))) -> #DIV/0! | L33: =IF(OR(K33=0,K33=90,K33=180,K33=270),K33,IF(AND(D32<D34,H32<H34),K33,IF(AND(D32<D34,H32>H34),360-K33,IF(AND(D32>D34,H32<H34),180-K33,IF(AND(D32>D34,H32>H34),180+K33))))) -> #DIV/0! | M33: =(IF(I33=0,G33,IF(G33=0,COS(D34*PI()/180)*I33,G33/COS(K33*PI()/180)))) -> 0 | N33: =IF(C35="","",ROUND(L33,1)) | O33: =IF(C35="","",ROUND(M33,1)) | T33: EVERY 15 MIN | V33: =(O33/P33+U33/60)/24 -> #VALUE!
A34: 11 | D34: =TRUNC(C34)+((C34-TRUNC(C34))/0.6) -> 0 | E34: =TRUNC(C35)+((C35-TRUNC(C35))/0.6) -> 0 | F34: =ROUND(((LOG10(TAN(PI()/4+(D34/2*PI()/180)))*7915.7046)-(3437.7468*((0.0816968^2*SIN(D34*PI()/180))+(0.0816968^4/3*((SIN(D34*PI()/180))^3))+(0.0816968^6/5*((SIN(D34*PI()/180))^5))))),2) -> 0 | H34: =IF(E34<0,E34+360,E34) -> 0 | Q34: =IF(O33="","",Q32+O33) | R34: =IF(O33="","",R32-O33) | T34: RADAR/GPS | W34: =IF(P33="","",W32+V33)
G35: =ABS(D34-D36)*60 -> 0 | I35: =ABS(H34-H36)*60 -> 0 | J35: =ABS(F34-F36) -> 0 | K35: =IF(AND(D34<D36,H34=H36),0,IF(AND(D34>D36,H34=H36),180,IF(AND(D34=D36,H34<H36),90,IF(AND(D34=D36,H34>H36),270,(ATAN(I35/J35)*180/PI()))))) -> #DIV/0! | L35: =IF(OR(K35=0,K35=90,K35=180,K35=270),K35,IF(AND(D34<D36,H34<H36),K35,IF(AND(D34<D36,H34>H36),360-K35,IF(AND(D34>D36,H34<H36),180-K35,IF(AND(D34>D36,H34>H36),180+K35))))) -> #DIV/0! | M35: =(IF(I35=0,G35,IF(G35=0,COS(D36*PI()/180)*I35,G35/COS(K35*PI()/180)))) -> 0 | N35: =IF(C37="","",ROUND(L35,1)) | O35: =IF(C37="","",ROUND(M35,1)) | T35: EVERY 15 MIN | V35: =(O35/P35+U35/60)/24 -> #VALUE!
A36: 12 | D36: =TRUNC(C36)+((C36-TRUNC(C36))/0.6) -> 0 | E36: =TRUNC(C37)+((C37-TRUNC(C37))/0.6) -> 0 | F36: =ROUND(((LOG10(TAN(PI()/4+(D36/2*PI()/180)))*7915.7046)-(3437.7468*((0.0816968^2*SIN(D36*PI()/180))+(0.0816968^4/3*((SIN(D36*PI()/180))^3))+(0.0816968^6/5*((SIN(D36*PI()/180))^5))))),2) -> 0 | H36: =IF(E36<0,E36+360,E36) -> 0 | Q36: =IF(O35="","",Q34+O35) | R36: =IF(O35="","",R34-O35) | T36: RADAR/GPS | W36: =IF(P35="","",W34+V35)
G37: =ABS(D36-D38)*60 -> 0 | I37: =ABS(H36-H38)*60 -> 0 | J37: =ABS(F36-F38) -> 0 | K37: =IF(AND(D36<D38,H36=H38),0,IF(AND(D36>D38,H36=H38),180,IF(AND(D36=D38,H36<H38),90,IF(AND(D36=D38,H36>H38),270,(ATAN(I37/J37)*180/PI()))))) -> #DIV/0! | L37: =IF(OR(K37=0,K37=90,K37=180,K37=270),K37,IF(AND(D36<D38,H36<H38),K37,IF(AND(D36<D38,H36>H38),360-K37,IF(AND(D36>D38,H36<H38),180-K37,IF(AND(D36>D38,H36>H38),180+K37))))) -> #DIV/0! | M37: =(IF(I37=0,G37,IF(G37=0,COS(D38*PI()/180)*I37,G37/COS(K37*PI()/180)))) -> 0 | N37: =IF(C39="","",ROUND(L37,1)) | O37: =IF(C39="","",ROUND(M37,1)) | T37: EVERY 30 MIN | V37: =(O37/P37+U37/60)/24 -> #VALUE!
A38: 13 | D38: =TRUNC(C38)+((C38-TRUNC(C38))/0.6) -> 0 | E38: =TRUNC(C39)+((C39-TRUNC(C39))/0.6) -> 0 | F38: =ROUND(((LOG10(TAN(PI()/4+(D38/2*PI()/180)))*7915.7046)-(3437.7468*((0.0816968^2*SIN(D38*PI()/180))+(0.0816968^4/3*((SIN(D38*PI()/180))^3))+(0.0816968^6/5*((SIN(D38*PI()/180))^5))))),2) -> 0 | H38: =IF(E38<0,E38+360,E38) -> 0 | Q38: =IF(O37="","",Q36+O37) | R38: =IF(O37="","",R36-O37) | T38: RADAR/GPS | W38: =IF(P37="","",W36+V37)
G39: =ABS(D38-D40)*60 -> 0 | I39: =ABS(H38-H40)*60 -> 0 | J39: =ABS(F38-F40) -> 0 | K39: =IF(AND(D38<D40,H38=H40),0,IF(AND(D38>D40,H38=H40),180,IF(AND(D38=D40,H38<H40),90,IF(AND(D38=D40,H38>H40),270,(ATAN(I39/J39)*180/PI()))))) -> #DIV/0! | L39: =IF(OR(K39=0,K39=90,K39=180,K39=270),K39,IF(AND(D38<D40,H38<H40),K39,IF(AND(D38<D40,H38>H40),360-K39,IF(AND(D38>D40,H38<H40),180-K39,IF(AND(D38>D40,H38>H40),180+K39))))) -> #DIV/0! | M39: =(IF(I39=0,G39,IF(G39=0,COS(D40*PI()/180)*I39,G39/COS(K39*PI()/180)))) -> 0 | N39: =IF(C41="","",ROUND(L39,1)) | O39: =IF(C41="","",ROUND(M39,1)) | T39: EVERY 30 MIN | V39: =(O39/P39+U39/60)/24 -> #VALUE!
A40: 14 | D40: =TRUNC(C40)+((C40-TRUNC(C40))/0.6) -> 0 | E40: =TRUNC(C41)+((C41-TRUNC(C41))/0.6) -> 0 | F40: =ROUND(((LOG10(TAN(PI()/4+(D40/2*PI()/180)))*7915.7046)-(3437.7468*((0.0816968^2*SIN(D40*PI()/180))+(0.0816968^4/3*((SIN(D40*PI()/180))^3))+(0.0816968^6/5*((SIN(D40*PI()/180))^5))))),2) -> 0 | H40: =IF(E40<0,E40+360,E40) -> 0 | Q40: =IF(O39="","",Q38+O39) | R40: =IF(O39="","",R38-O39) | T40: GPS | W40: =IF(P39="","",W38+V39)
G41: =ABS(D40-D42)*60 -> 0 | I41: =ABS(H40-H42)*60 -> 0 | J41: =ABS(F40-F42) -> 0 | K41: =IF(AND(D40<D42,H40=H42),0,IF(AND(D40>D42,H40=H42),180,IF(AND(D40=D42,H40<H42),90,IF(AND(D40=D42,H40>H42),270,(ATAN(I41/J41)*180/PI()))))) -> #DIV/0! | L41: =IF(OR(K41=0,K41=90,K41=180,K41=270),K41,IF(AND(D40<D42,H40<H42),K41,IF(AND(D40<D42,H40>H42),360-K41,IF(AND(D40>D42,H40<H42),180-K41,IF(AND(D40>D42,H40>H42),180+K41))))) -> #DIV/0! | M41: =(IF(I41=0,G41,IF(G41=0,COS(D42*PI()/180)*I41,G41/COS(K41*PI()/180)))) -> 0 | N41: =IF(C43="","",ROUND(L41,1)) | O41: =IF(C43="","",ROUND(M41,1)) | T41: EVERY 1 HR. | V41: =(O41/P41+U41/60)/24 -> #VALUE!
...

Sheet SAMPLE
A1: BRIDGE NOTE BOOK (CONFINED WATERS PASSAGE PLAN)
A2: (MV PLUTO LEADER)
A3: DATE :17 AUG. 2021 | N3: VOY. NO. : 028 | R3: FROM: NAGOYA, KINJYO | V3: TO: YOKOHAMA, DAIKUKO | AA3: MAX DRAFT: 9.0M | AD3: AVE.SPD.16.0 KTS
A5: NO. | B5: WAY POINT & POSITION | N5: CO. | O5: DIST | P5: SP'D | Q5: F'M | R5: TO | S5: ESTIMATED | T5: POSITION | U5: TIME CORR. (min.) | W5: ETA/ETP (L.T.) | X5: POSITION FIX | Y5: POSITION | Z5: CALL | AA5: WATCH | AB5: CHART NO. | AC5: GARBAGE/ | AD5: REMARKS:
S6: MINIMUM (UKC) | T6: FIX SYSTEM | X6: SYSTEM | Y6: FIXING | Z6: CAPT. | AA6: LEVEL | AC6: SEWAGE/
D7: Lat | E7: Long | F7: 漸長緯度 | G7: 緯差 | H7: Long (360) | I7: 経差 | J7: 漸長緯度差 | L7: 針路 | M7: 距離 | S7: E (ENOUGH) OR | T7: PRIMARY | X7: PRIMARY | Y7: FREQUENCY | Z7: Y: | AA7: 1, 2 &3 | AC7: Y/N
S8: ACTUAL METER | T8: SECONDARY | X8: SECONDARY | Y8: (MIN) | Z8: YES | AC8: DISPOSAL
A9: =IF(B9="","",1) -> 1 | B9: KINJO WHARF NO. 76 & 77 | C9: 35.0303 | D9: =TRUNC(C9)+((C9-TRUNC(C9))/0.6) -> 35.0505 | E9: =TRUNC(C10)+((C10-TRUNC(C10))/0.6) -> 136.83817 | F9: =ROUND(((LOG10(TAN(PI()/4+(D9/2*PI()/180)))*7915.7046)-(3437.7468*((0.0816968^2*SIN(D9*PI()/180))+(0.0816968^4/3*((SIN(D9*PI()/180))^3))+(0.0816968^6/5*((SIN(D9*PI()/180))^5))))),2) -> 2234.8 | H9: =IF(E9<0,E9+360,E9) -> 136.83817 | Q9: =IF(O10="","",0) -> 0 | R9: 224.8 | T9: RADAR | X9: VIS, XB | AD9: ECDIS ROUTE NAME: 1) NGO - OUT (OUTBOUND) --->2) NGO-YOK VOY. 028 (AUG. 2021) ---> 3) YOK-IN ( INBOUND)
C10: 136.5029 | G10: =ABS(D9-D11)*60 -> 1.03 | I10: =ABS(H9-H11)*60 -> 0.21 | J10: =ABS(F9-F11) -> 1.25 | K10: =IF(AND(D9<D11,H9=H11),0,IF(AND(D9>D11,H9=H11),180,IF(AND(D9=D11,H9<H11),90,IF(AND(D9=D11,H9>H11),270,(ATAN(I10/J10)*180/PI()))))) -> 9.5366358 | L10: =IF(OR(K10=0,K10=90,K10=180,K10=270),K10,IF(AND(D9<D11,H9<H11),K10,IF(AND(D9<D11,H9>H11),360-K10,IF(AND(D9>D11,H9<H11),180-K10,IF(AND(D9>D11,H9>H11),180+K10))))) -> 170.46336 | M10: =(IF(I10=0,G10,IF(G10=0,COS(D11*PI()/180)*I10,G10/COS(K10*PI()/180)))) -> 1.0444342 | N10: =IF(C12="","",ROUND(L10,1)) -> 170.5 | O10: =IF(C12="","",ROUND(M10,1)) -> 1 | P10: 2 | S10: 2.1 | T10: EVERY 5 MIN | V10: =(O10/P10+U10/60)/24 -> 0.020833333 | X10: RD, GPS | Y10: 5-15 | Z10: Y | AA10: 3 | AB10: JP1055A | AC10: N
A11: =IF(B11="","",A9+1) -> 2 | B11: OFF KINJO BERTH | C11: 35.02 | D11: =TRUNC(C11)+((C11-TRUNC(C11))/0.6) -> 35.033333 | E11: =TRUNC(C12)+((C12-TRUNC(C12))/0.6) -> 136.84167 | F11: =ROUND(((LOG10(TAN(PI()/4+(D11/2*PI()/180)))*7915.7046)-(3437.7468*((0.0816968^2*SIN(D11*PI()/180))+(0.0816968^4/3*((SIN(D11*PI()/180))^3))+(0.0816968^6/5*((SIN(D11*PI()/180))^5))))),2) -> 2233.55 | H11: =IF(E11<0,E11+360,E11) -> 136.84167 | Q11: =IF(O10="","",Q9+O10) -> 1 | R11: =IF(O10="","",R9-O10) -> 223.8 | T11: RADAR | W11: =IF(P10="","",W9+V10) -> 0.020833333 | X11: VIS, XB | AD11: ASSIST PILOT FOR EMBARKATION
C12: 136.505 | G12: =ABS(D11-D13)*60 -> 0.65 | I12: =ABS(H11-H13)*60 -> 0.15 | J12: =ABS(F11-F13) -> 0.79 | K12: =IF(AND(D11<D13,H11=H13),0,IF(AND(D11>D13,H11=H13),180,IF(AND(D11=D13,H11<H13),90,IF(AND(D11=D13,H11>H13),270,(ATAN(I12/J12)*180/PI()))))) -> 10.750967 | L12: =IF(OR(K12=0,K12=90,K12=180,K12=270),K12,IF(AND(D11<D13,H11<H13),K12,IF(AND(D11<D13,H11>H13),360-K12,IF(AND(D11>D13,H11<H13),180-K12,IF(AND(D11>D13,H11>H13),180+K12))))) -> 169.24903 | M12: =(IF(I12=0,G12,IF(G12=0,COS(D13*PI()/180)*I12,G12/COS(K12*PI()/180)))) -> 0.66161313 | N12: =IF(C14="","",ROUND(L12,1)) -> 169.2 | O12: =IF(C14="","",ROUND(M12,1)) -> 0.7 | P12: 5 | S12: 6.9 | T12: EVERY 5 MIN | V12: =(O12/P12+U12/60)/24 -> 0.0058333333 | X12: RD, GPS | Y12: 5-15 | Z12: Y | AA12: 3 | AB12: JP1055A | AC12: N
